Workbook

Sheet Missing Report Comm.-DE
B1: ADVERTISING MISSING REPORT, COMMERCIAL
B2: 30 Jul 25 to 05 Aug 25
R3: Numbers = Cms
B4: KARACHI | H4: 30'Jul to 05'Aug | K4: 01'Jul to 05'Aug
B5: Sr.# | C5: Clients | D5: Brands | E5: Agency Name | F5: Category | G5: Marketing Executive | H5: EXP | I5: JANG | J5: NWQ | K5: EXP | L5: JANG | M5: NWQ | N5: % change vs Jang | O5: % change vs. NWQ | P5: # of Visits | Q5: Estimated Value of Adv. | R5: Minutes Of Meeting | AL5: Feb'24
B6: 1 | C6: SONERI BANK (KARACHI) | D6: SONERI BANK LIMITED (CORPORATE) | E6: OMD | F6: ROP | H6: 0 | I6: 2160 | J6: 0 | K6: 0 | L6: 2160 | M6: 0 | N6: =IFERROR(K6/L6-1,0) -> -1 | O6: =IFERROR(K6/M6-1,0) -> 0 | R6: Management of Soneri Bank wants to advertise in only Jang for its one of ad in urdu newspapers.
B8: ISLAMABAD | H8: =+H4 -> 30'Jul to 05'Aug | K8: =+K4 -> 01'Jul to 05'Aug
B9: Sr.# | C9: Clients | D9: Brands | E9: Agency Name | F9: Category | G9: Marketing Executive | H9: EXP | I9: JANG | J9: NWQ | K9: EXP | L9: JANG | M9: NWQ | N9: % change vs Jang | O9: % change vs. NWQ | P9: # of Visits | Q9: Estimated Value of Adv. | R9: Minutes Of Meeting
B10: 1 | C10: ASKARI COMMERCIAL BANK (ISB) | D10: ASKARI BANK (HAJJ POLICY) | E10: Group M, Khi | F10: ROP | G10: Muneer Hussein | H10: 0 | I10: 540 | J10: 432 | K10: 0 | L10: 540 | M10: 432 | N10: =IFERROR(K10/L10-1,0) -> -1 | O10: =IFERROR(K10/M10-1,0) -> -1 | R10: It is published in Express, combined on 6th August at Back-page.
B11: 2 | C11: MAROOF INTERNATIONAL HOSPITAL | D11: MAROOF INTERNATIONAL HOSPITAL | E11: Orient | F11: ROP | G11: Farrukh Abbasi | H11: 0 | I11: 60 | J11: 0 | K11: 0 | L11: 120 | M11: 0 | N11: =IFERROR(K11/L11-1,0) -> -1 | O11: =IFERROR(K11/M11-1,0) -> 0 | R11: This is JMW magazine deal ad. Client has refused magazine deal with Express.
B12: 3 | C12: CAPITAL UNIVERSITY OF SCIENCE AND TECHNOLOGY | D12: CAPITAL UNIVERSITY OF SCIENCE AND TECHNO | E12: Impact Advt. Lhr | F12: EDU | G12: Faizan Bin Ishtaique | H12: 0 | I12: 216 | J12: 216 | K12: 0 | L12: 216 | M12: 216 | N12: =IFERROR(K12/L12-1,0) -> -1 | O12: =IFERROR(K12/M12-1,0) -> -1 | R12: Old name MAJU now is CUST & released from Lahore.
B13: 4 | C13: MY UNIVERSITY | D13: MY UNIVERSITY | E13: C J / Smartways | F13: EDU | G13: Faizan Bin Ishtaique | H13: 0 | I13: 60 | J13: 0 | K13: 0 | L13: 240 | M13: 0 | N13: =IFERROR(K13/L13-1,0) -> -1 | O13: =IFERROR(K13/M13-1,0) -> 0 | R13: Follow-up in progress.
B17: LAHORE | H17: =+H4 -> 30'Jul to 05'Aug | K17: =+K8 -> 01'Jul to 05'Aug
B18: Sr.# | C18: Clients | D18: Brands | E18: Agency Name | F18: Category | G18: Marketing Executive | H18: EXP | I18: JANG | J18: NWQ | K18: EXP | L18: JANG | M18: NWQ | N18: % change vs Jang | O18: % change vs. NWQ | P18: # of Visits | Q18: Estimated Value of Adv. | R18: Minutes Of Meeting | S18: `
B19: 1 | C19: GLOBAL ECONO TRADE (PVT) LTD | D19: GLOBAL ECONO TRADE (PVT) LTD | E19: Sv | F19: ROP | G19: Shirmeen Khurram/Suleman Afzal | H19: 0 | I19: 240 | J19: 0 | K19: 0 | L19: 540 | M19: 0 | N19: =IFERROR(K19/L19-1,0) -> -1 | O19: =IFERROR(K19/M19-1,0) -> 0 | R19: Rate given to client but client did not given approval
B20: =B19+1 -> 2 | C20: GLOBAL ECONO TRADE (PVT) LTD | D20: TREET HYGIENE RAZOR | E20: SV | F20: ROP | G20: Shirmeen Khurram/Suleman Afzal | H20: 0 | I20: 0 | J20: 420 | K20: 0 | L20: 660 | M20: 660 | N20: =IFERROR(K20/L20-1,0) -> -1 | O20: =IFERROR(K20/M20-1,0) -> -1 | R20: Rate given to client but client did not given approval
B21: =B20+1 -> 3 | C21: BEACONHOUSE NATIONAL UNIVERSITY | D21: BEACONHOUSE NATIONAL UNIVERSITY | E21: CJ | F21: EDU | G21: Shirmeen Khurram / Raja Naseer | H21: 0 | I21: 924 | J21: 0 | K21: 0 | L21: 924 | M21: 0 | N21: =IFERROR(K21/L21-1,0) -> -1 | O21: =IFERROR(K21/M21-1,0) -> 0 | R21: Jang priorety.
B22: =B21+1 -> 4 | C22: FALCON EDUCATION & CONSULTANCY SERVICES | D22: FALCON EDUCATION & CONSULTANCY SERVICES | E22: Direct | F22: EDU | G22: Shirmeen Khurram / Raja Naseer | H22: 0 | I22: 117 | J22: 0 | K22: 0 | L22: 249 | M22: 0 | N22: =IFERROR(K22/L22-1,0) -> -1 | O22: =IFERROR(K22/M22-1,0) -> 0 | R22: Jang priorety ,He is friend of Mr Sarmad Ali.
B23: =B22+1 -> 5 | C23: UNIQUE GROUP OF INSTITUTIONS | D23: UNIQUE GROUP OF INSTITUTIONS | E23: Velocity | F23: EDU | G23: Shirmeen Khurram / Raja Naseer | H23: 0 | I23: 540 | J23: 0 | K23: 0 | L23: 756 | M23: 0 | N23: =IFERROR(K23/L23-1,0) -> -1 | O23: =IFERROR(K23/M23-1,0) -> 0 | R23: Jang priorety broad sheet ad.
B24: =B23+1 -> 6 | C24: UNIVERSITY OF MANAGEMENT & TECHNOLOGY | D24: UNIVERSITY OF MANAGEMENT&TECHNOLOGY(UMT) | E24: Fv | F24: EDU | G24: Shirmeen Khurram / Raja Naseer | H24: 0 | I24: 0 | J24: 360 | K24: 360 | L24: 1260 | M24: 360 | N24: =IFERROR(K24/L24-1,0) -> -0.71428571 | O24: =IFERROR(K24/M24-1,0) -> 0 | R24: Published on 11, July 15x8 Guj+Fsd+Sar+Mul+Isb. & pubished 13, july 15x8 only lhr DE.

Sheet Missing Report Comm.-ET
B1: ADVERTISING MISSING REPORT, COMMERCIAL
B2: 30 Jul 25 to 05 Aug 25
S3: Numbers = Cms
B4: KARACHI | I4: 30'Jul to 05'Aug | L4: 01'Jul to 05'Aug
B5: Sr.# | C5: Clients | D5: Brands | E5: Agency Name | F5: Category | G5: Agency | H5: Marketing Executive | I5: ET | J5: DAWN | K5: NEWS | L5: ET | M5: DAWN | N5: NEWS | O5: % change vs Dawn | P5: % change vs The News | Q5: # of Visits | R5: Estimated Value of Adv. | S5: Minutes Of Meeting
B6: 1 | C6: HONDA ATLAS | D6: HONDA (CG-125)DELUX | E6: Adcom | F6: ROP | H6: Zain/Khilji | I6: 0 | J6: 360 | K6: 0 | L6: 0 | M6: 720 | N6: 0 | O6: =IFERROR(L6/M6-1,0) -> -1 | P6: =IFERROR(L6/N6-1,0) -> 0 | S6: We have exclusive ad in DE on 30th, 31st july 15x8 and on 6th Aug ( Half Page), they Opted dawn only as english newspapers
B7: 2 | F7: ROP | O7: =IFERROR(L7/M7-1,0) -> 0 | P7: =IFERROR(L7/N7-1,0) -> 0
B8: 1 | C8: SONERI BANK (KARACHI) | D8: SONERI BANK LIMITED (CORPORATE) | E8: OMD | F8: ROP | H8: Kamran Khilji / Zohaib Waheed | I8: 0 | J8: 1296 | K8: 0 | L8: 0 | M8: 1296 | N8: 0 | O8: =IFERROR(L8/M8-1,0) -> -1 | P8: =IFERROR(L8/N8-1,0) -> 0 | S8: Management of Soneri Bank wants to advertise in only Dawn for its one of ad in English newspapers.
B11: ISLAMABAD | I11: =+I4 -> 30'Jul to 05'Aug | L11: =+L4 -> 01'Jul to 05'Aug
B13: Sr.# | C13: Clients | D13: Brands | E13: Agency Name | F13: Category | G13: Agency | H13: Marketing Executive | I13: ET | J13: DAWN | K13: NEWS | L13: ET | M13: DAWN | N13: NEWS | O13: % change vs Dawn | P13: % change vs The News | Q13: # of Visits | R13: Estimated Value of Adv. | S13: Minutes Of Meeting
B14: 1 | C14: MAROOF INTERNATIONAL HOSPITAL | D14: MAROOF INTERNATIONAL HOSPITAL | E14: Orient | F14: ROP | H14: Farrukh Abbasi | I14: 0 | J14: 0 | K14: 60 | L14: 0 | M14: 0 | N14: 120 | O14: =IFERROR(L14/M14-1,0) -> 0 | P14: =IFERROR(L14/N14-1,0) -> -1 | S14: This is JMW magazine deal ad. Client has refused magazine deal with Tribune.
B18: LAHORE | I18: =+I4 -> 30'Jul to 05'Aug | L18: =+L4 -> 01'Jul to 05'Aug
B20: Sr.# | C20: Clients | D20: Brands | E20: Agency Name | F20: Category | G20: Agency | H20: Marketing Executive | I20: ET | J20: DAWN | K20: NEWS | L20: ET | M20: DAWN | N20: NEWS | O20: % change vs Dawn | P20: % change vs The News | Q20: # of Visits | R20: Estimated Value of Adv. | S20: Minutes Of Meeting | AL20: Feb'24
B21: 1 | C21: BEACONHOUSE NATIONAL UNIVERSITY | D21: BEACONHOUSE NATIONAL UNIVERSITY | E21: CJ | F21: EDU | H21: Shirmeen khurram / Raja Naseer | I21: 0 | J21: 360 | K21: 0 | L21: 0 | M21: 360 | N21: 0 | O21: =IFERROR(L21/M21-1,0) -> -1 | P21: =IFERROR(L21/N21-1,0) -> 0 | R21: Jang News priority, this ad against Expo deal, Working on it. | S21: Dawn priorety.

Sheet Missing Report Govt.-DE
B1: ADVERTISING MISSING REPORT, GOVERNMENT
B2: 30 Jul 25 to 05 Aug 25
Q3: Numbers = Cms
H4: 30'Jul to 05'Aug | K4: 01'Jul to 05'Aug
B5: Sr.# | C5: Clients | D5: Category | E5: Agency Name | F5: City | G5: Marketing Executive | H5: EXP | I5: JANG | J5: NWQT | K5: EXP | L5: JANG | M5: NWQT | N5: % change vs JANG | O5: % change vs NWQT | P5: # of Visits | Q5: Minutes Of Meeting | AK5: Feb'24
B6: 1 | C6: KARACHI INFRASTRUCTURE DEVELOPMENT COMPANY LIMITED (KIDCL) | D6: PID(K) | E6: PID | F6: Karachi | G6: Kashif Nazeer | H6: 0 | I6: 2160 | J6: 0 | K6: 648 | L6: 2250 | M6: 216 | N6: =IFERROR(K6/L6-1,0) -> -0.712 | O6: =IFERROR(K6/M6-1,0) -> 2 | Q6: As per govt policy media fainalize by PID and they have release their ads CM wise not Client wise.
C7: PAKISTAN INTERNATIONAL AIRLINES (PIA) | D7: PID(K) | E7: PID | F7: Karachi | G7: Irshad Ali | H7: 198 | I7: 564 | J7: 312 | K7: 570 | L7: 1983 | M7: 714 | N7: =IFERROR(K7/L7-1,0) -> -0.71255673 | O7: =IFERROR(K7/M7-1,0) -> -0.20168067 | Q7: As per govt policy media fainalize by PID and they have release their ads CM wise not Client wise.
C8: TRADING CORPORATION OF PAKISTAN(TCP) | D8: PID(K) | E8: PID | F8: Karachi | G8: Irshad Ali | H8: 240 | I8: 484 | J8: 60 | K8: 482 | L8: 1429 | M8: 181 | N8: =IFERROR(K8/L8-1,0) -> -0.66270119 | O8: =IFERROR(K8/M8-1,0) -> 1.6629834 | Q8: As per govt policy media fainalize by PID and they have release their ads CM wise not Client wise.
B9: =B6+1 -> 2 | C9: NATIONAL INSURANCE COMPANY LTD. | D9: PID(K) | E9: PID | F9: Karachi | G9: Kashif Nazeer | H9: 0 | I9: 480 | J9: 135 | K9: 0 | L9: 480 | M9: 179 | N9: =IFERROR(K9/L9-1,0) -> -1 | O9: =IFERROR(K9/M9-1,0) -> -1 | Q9: As per govt policy media fainalize by PID and they have release their ads CM wise not Client wise.
B10: =B9+1 -> 3 | C10: SUI SOUTHERN GAS COMPANY (SSGC) | D10: PID(K) | E10: PID | F10: Karachi | G10: Kashif Nazeer | H10: 80 | I10: 240 | J10: 0 | K10: 352 | L10: 672 | M10: 0 | N10: =IFERROR(K10/L10-1,0) -> -0.47619048 | O10: =IFERROR(K10/M10-1,0) -> 0 | Q10: As per govt policy media fainalize by PID and they have release their ads CM wise not Client wise.

Sheet Missing Report Govt.-ET
B1: ADVERTISING MISSING REPORT, GOVERNMENT
B2: 30 Jul 25 to 05 Aug 25
I4: 30'Jul to 05'Aug | L4: 01'Jul to 05'Aug
B5: Sr.# | C5: Clients | D5: Category | E5: Agency Name | F5: City | G5: Agency | H5: Marketing Executive | I5: ET | J5: DAWN | K5: NEWS | L5: ET | M5: DAWN | N5: NEWS | O5: % change vs Dawn | P5: % change vs The News | Q5: # of Visits | R5: Estimated Value of Adv. | S5: Minutes Of Meeting | AM5: Feb'24
B6: 1 | C6: STATE BANK OF PAKISTAN (SBP) | D6: PID(K) | E6: PID | F6: Karachi | H6: Irshad Ali | I6: 0 | J6: 0 | K6: 108 | L6: 198 | M6: 0 | N6: 753 | O6: =IFERROR(L6/M6-1,0) -> 0 | P6: =IFERROR(L6/N6-1,0) -> -0.73705179 | S6: As per govt policy media fainalize by PID and they have release their ads CM wise not Client wise.

Sheet FED-PID(ALL)
A1: Total PIDs Revenues (Federal Government)
A2: From 01/01/2021 To 05/8/2025
A4: Rs in million
B5: Jan'21 | C5: Feb'21 | D5: Mar'21 | E5: Apr'21 | F5: May'21 | G5: Jun'21 | H5: Jul'21 | I5: Aug'21 | J5: Sep'21 | K5: Oct'21 | L5: Nov'21 | M5: Dec'21 | N5: Jan'22 | O5: Feb'22 | P5: Mar'22 | Q5: Apr'22 | R5: May'22 | S5: Jun'22 | T5: Jul'22 | U5: Aug'22 | V5: Sep'22 | W5: Oct'22 | X5: Nov'22 | Y5: Dec'22 | Z5: Jan'23 | AA5: Feb'23 | AB5: Mar'23 | AC5: Apr'23 | AD5: May'23 | AE5: Jun'23 | AF5: Jul'23 | AG5: Aug'23 | AH5: Sep'23 | AI5: Oct'23 | AJ5: Nov'23 | AK5: Dec'23 | AL5: Jan'24 | AM5: Feb'24 | AN5: Mar'24 | AO5: Apr'24 | AP5: May'24 | AQ5: Jun'24 | AR5: Jul'24 | AS5: Aug'24 | AT5: Sep'24 | AU5: Oct'24 | AV5: Nov'24 | AW5: Dec'24 | AX5: Jan'25 | AY5: Feb'25 | AZ5: Mar'25 | BA5: Apr'25 | BB5: May'25 | BC5: Jun'25 | BD5: Jul'25 | BE5: 1-5-Aug'25 | BF5: TOTAL
A6: URDU DAILIES
A7: Jang | B7: =IFERROR('FED-PID(I)'!B7+'FED-PID(K)'!B7+'FED-PID(L)'!B7+'FED-PID(P)'!B7,"") -> 15.09734 | C7: =IFERROR('FED-PID(I)'!C7+'FED-PID(K)'!C7+'FED-PID(L)'!C7+'FED-PID(P)'!C7,"") -> 10.691751 | D7: =IFERROR('FED-PID(I)'!D7+'FED-PID(K)'!D7+'FED-PID(L)'!D7+'FED-PID(P)'!D7,"") -> 10.29 | E7: =IFERROR('FED-PID(I)'!E7+'FED-PID(K)'!E7+'FED-PID(L)'!E7+'FED-PID(P)'!E7,"") -> 5.6 | F7: =IFERROR('FED-PID(I)'!F7+'FED-PID(K)'!F7+'FED-PID(L)'!F7+'FED-PID(P)'!F7,"") -> 12.879561 | G7: =IFERROR('FED-PID(I)'!G7+'FED-PID(K)'!G7+'FED-PID(L)'!G7+'FED-PID(P)'!G7,"") -> 10.394322 | H7: =IFERROR('FED-PID(I)'!H7+'FED-PID(K)'!H7+'FED-PID(L)'!H7+'FED-PID(P)'!H7,"") -> 11.328498 | I7: =IFERROR('FED-PID(I)'!I7+'FED-PID(K)'!I7+'FED-PID(L)'!I7+'FED-PID(P)'!I7,"") -> 12.018702 | ... AQ7: =IFERROR('FED-PID(I)'!AQ7+'FED-PID(K)'!AQ7+'FED-PID(L)'!AQ7+'FED-PID(P)'!AQ7,"") -> 32.212635 | AR7: ='FED-PID(K)'!AR7+'FED-PID(L)'!AR7+'FED-PID(I)'!AR7+'FED-PID(P)'!AR7 -> 29.44508 | AS7: ='FED-PID(K)'!AS7+'FED-PID(L)'!AS7+'FED-PID(I)'!AS7+'FED-PID(P)'!AS7 -> 37.099255 | AT7: ='FED-PID(K)'!AT7+'FED-PID(L)'!AT7+'FED-PID(I)'!AT7+'FED-PID(P)'!AT7 -> 36.020275 | AU7: ='FED-PID(K)'!AU7+'FED-PID(L)'!AU7+'FED-PID(I)'!AU7+'FED-PID(P)'!AU7 -> 30.274132 | AV7: ='FED-PID(K)'!AV7+'FED-PID(L)'!AV7+'FED-PID(I)'!AV7+'FED-PID(P)'!AV7 -> 29.486003 | AW7: ='FED-PID(K)'!AW7+'FED-PID(L)'!AW7+'FED-PID(I)'!AW7+'FED-PID(P)'!AW7 -> 41.110961 | AX7: ='FED-PID(K)'!AX7+'FED-PID(L)'!AX7+'FED-PID(I)'!AX7+'FED-PID(P)'!AX7 -> 32.890629 | AY7: ='FED-PID(K)'!AY7+'FED-PID(L)'!AY7+'FED-PID(I)'!AY7+'FED-PID(P)'!AY7 -> 35.153729 | ... BE7: ='FED-PID(K)'!BE7+'FED-PID(L)'!BE7+'FED-PID(I)'!BE7+'FED-PID(P)'!BE7 -> 5.630406 | BF7: =SUM(OFFSET(BF7,0,-1,):OFFSET(BF7,0,-8)) -> 263.85188
A8: Nawa-e-Waqt | B8: =IFERROR('FED-PID(I)'!B8+'FED-PID(K)'!B8+'FED-PID(L)'!B8+'FED-PID(P)'!B8,"") -> 6.907712 | C8: =IFERROR('FED-PID(I)'!C8+'FED-PID(K)'!C8+'FED-PID(L)'!C8+'FED-PID(P)'!C8,"") -> 7.841268 | D8: =IFERROR('FED-PID(I)'!D8+'FED-PID(K)'!D8+'FED-PID(L)'!D8+'FED-PID(P)'!D8,"") -> 7.52 | E8: =IFERROR('FED-PID(I)'!E8+'FED-PID(K)'!E8+'FED-PID(L)'!E8+'FED-PID(P)'!E8,"") -> 7.1 | F8: =IFERROR('FED-PID(I)'!F8+'FED-PID(K)'!F8+'FED-PID(L)'!F8+'FED-PID(P)'!F8,"") -> 7.106668 | G8: =IFERROR('FED-PID(I)'!G8+'FED-PID(K)'!G8+'FED-PID(L)'!G8+'FED-PID(P)'!G8,"") -> 7.72515 | H8: =IFERROR('FED-PID(I)'!H8+'FED-PID(K)'!H8+'FED-PID(L)'!H8+'FED-PID(P)'!H8,"") -> 7.072632 | I8: =IFERROR('FED-PID(I)'!I8+'FED-PID(K)'!I8+'FED-PID(L)'!I8+'FED-PID(P)'!I8,"") -> 12.081801 | ... AQ8: =IFERROR('FED-PID(I)'!AQ8+'FED-PID(K)'!AQ8+'FED-PID(L)'!AQ8+'FED-PID(P)'!AQ8,"") -> 7.74 | AR8: ='FED-PID(K)'!AR8+'FED-PID(L)'!AR8+'FED-PID(I)'!AR8+'FED-PID(P)'!AR8 -> 10.785364 | AS8: ='FED-PID(K)'!AS8+'FED-PID(L)'!AS8+'FED-PID(I)'!AS8+'FED-PID(P)'!AS8 -> 12.732163 | AT8: ='FED-PID(K)'!AT8+'FED-PID(L)'!AT8+'FED-PID(I)'!AT8+'FED-PID(P)'!AT8 -> 9.391413 | AU8: ='FED-PID(K)'!AU8+'FED-PID(L)'!AU8+'FED-PID(I)'!AU8+'FED-PID(P)'!AU8 -> 12.58 | AV8: ='FED-PID(K)'!AV8+'FED-PID(L)'!AV8+'FED-PID(I)'!AV8+'FED-PID(P)'!AV8 -> 7.743317 | AW8: ='FED-PID(K)'!AW8+'FED-PID(L)'!AW8+'FED-PID(I)'!AW8+'FED-PID(P)'!AW8 -> 11.499045 | AX8: ='FED-PID(K)'!AX8+'FED-PID(L)'!AX8+'FED-PID(I)'!AX8+'FED-PID(P)'!AX8 -> 7.947808 | AY8: ='FED-PID(K)'!AY8+'FED-PID(L)'!AY8+'FED-PID(I)'!AY8+'FED-PID(P)'!AY8 -> 8.511337 | ... BE8: ='FED-PID(K)'!BE8+'FED-PID(L)'!BE8+'FED-PID(I)'!BE8+'FED-PID(P)'!BE8 -> 1.911112 | BF8: =SUM(OFFSET(BF8,0,-1,):OFFSET(BF8,0,-8)) -> 68.070666
A9: Dunya | B9: =IFERROR('FED-PID(I)'!B9+'FED-PID(K)'!B9+'FED-PID(L)'!B9+'FED-PID(P)'!B9,"") -> 7.553686 | C9: =IFERROR('FED-PID(I)'!C9+'FED-PID(K)'!C9+'FED-PID(L)'!C9+'FED-PID(P)'!C9,"") -> 7.24256 | D9: =IFERROR('FED-PID(I)'!D9+'FED-PID(K)'!D9+'FED-PID(L)'!D9+'FED-PID(P)'!D9,"") -> 6.2 | E9: =IFERROR('FED-PID(I)'!E9+'FED-PID(K)'!E9+'FED-PID(L)'!E9+'FED-PID(P)'!E9,"") -> 6.72 | F9: =IFERROR('FED-PID(I)'!F9+'FED-PID(K)'!F9+'FED-PID(L)'!F9+'FED-PID(P)'!F9,"") -> 4.793114 | G9: =IFERROR('FED-PID(I)'!G9+'FED-PID(K)'!G9+'FED-PID(L)'!G9+'FED-PID(P)'!G9,"") -> 6.357667 | H9: =IFERROR('FED-PID(I)'!H9+'FED-PID(K)'!H9+'FED-PID(L)'!H9+'FED-PID(P)'!H9,"") -> 7.515457 | I9: =IFERROR('FED-PID(I)'!I9+'FED-PID(K)'!I9+'FED-PID(L)'!I9+'FED-PID(P)'!I9,"") -> 8.945556 | ... AQ9: =IFERROR('FED-PID(I)'!AQ9+'FED-PID(K)'!AQ9+'FED-PID(L)'!AQ9+'FED-PID(P)'!AQ9,"") -> 7.08 | AR9: ='FED-PID(K)'!AR9+'FED-PID(L)'!AR9+'FED-PID(I)'!AR9+'FED-PID(P)'!AR9 -> 10.950355 | AS9: ='FED-PID(K)'!AS9+'FED-PID(L)'!AS9+'FED-PID(I)'!AS9+'FED-PID(P)'!AS9 -> 12.092834 | AT9: ='FED-PID(K)'!AT9+'FED-PID(L)'!AT9+'FED-PID(I)'!AT9+'FED-PID(P)'!AT9 -> 14.047429 | AU9: ='FED-PID(K)'!AU9+'FED-PID(L)'!AU9+'FED-PID(I)'!AU9+'FED-PID(P)'!AU9 -> 15.85 | AV9: ='FED-PID(K)'!AV9+'FED-PID(L)'!AV9+'FED-PID(I)'!AV9+'FED-PID(P)'!AV9 -> 13.220371 | AW9: ='FED-PID(K)'!AW9+'FED-PID(L)'!AW9+'FED-PID(I)'!AW9+'FED-PID(P)'!AW9 -> 16.811314 | AX9: ='FED-PID(K)'!AX9+'FED-PID(L)'!AX9+'FED-PID(I)'!AX9+'FED-PID(P)'!AX9 -> 13.098812 | AY9: ='FED-PID(K)'!AY9+'FED-PID(L)'!AY9+'FED-PID(I)'!AY9+'FED-PID(P)'!AY9 -> 17.908795 | ... BE9: ='FED-PID(K)'!BE9+'FED-PID(L)'!BE9+'FED-PID(I)'!BE9+'FED-PID(P)'!BE9 -> 2.616432 | BF9: =SUM(OFFSET(BF9,0,-1,):OFFSET(BF9,0,-8)) -> 120.46233
A10: Express | B10: =IFERROR('FED-PID(I)'!B10+'FED-PID(K)'!B10+'FED-PID(L)'!B10+'FED-PID(P)'!B10,"") -> 16.155117 | C10: =IFERROR('FED-PID(I)'!C10+'FED-PID(K)'!C10+'FED-PID(L)'!C10+'FED-PID(P)'!C10,"") -> 13.579529 | D10: =IFERROR('FED-PID(I)'!D10+'FED-PID(K)'!D10+'FED-PID(L)'!D10+'FED-PID(P)'!D10,"") -> 10.83 | E10: =IFERROR('FED-PID(I)'!E10+'FED-PID(K)'!E10+'FED-PID(L)'!E10+'FED-PID(P)'!E10,"") -> 12.55 | F10: =IFERROR('FED-PID(I)'!F10+'FED-PID(K)'!F10+'FED-PID(L)'!F10+'FED-PID(P)'!F10,"") -> 13.917995 | G10: =IFERROR('FED-PID(I)'!G10+'FED-PID(K)'!G10+'FED-PID(L)'!G10+'FED-PID(P)'!G10,"") -> 12.52823 | H10: =IFERROR('FED-PID(I)'!H10+'FED-PID(K)'!H10+'FED-PID(L)'!H10+'FED-PID(P)'!H10,"") -> 14.475679 | I10: =IFERROR('FED-PID(I)'!I10+'FED-PID(K)'!I10+'FED-PID(L)'!I10+'FED-PID(P)'!I10,"") -> 21.382632 | ... AI10: =IFERROR('FED-PID(I)'!AI10+'FED-PID(K)'!AI10+'FED-PID(L)'!AI10+'FED-PID(P)'!AI10,"") -> 9.692603 | AJ10: =IFERROR('FED-PID(I)'!AJ10+'FED-PID(K)'!AJ10+'FED-PID(L)'!AJ10+'FED-PID(P)'!AJ12,"") -> 14.401557 | AK10: =IFERROR('FED-PID(I)'!AK10+'FED-PID(K)'!AK10+'FED-PID(L)'!AK10+'FED-PID(P)'!AK12,"") -> 16.202769 | AL10: =IFERROR('FED-PID(I)'!AL10+'FED-PID(K)'!AL10+'FED-PID(L)'!AL10+'FED-PID(P)'!AL12,"") -> 9.443407 | AM10: =IFERROR('FED-PID(I)'!AM10+'FED-PID(K)'!AM10+'FED-PID(L)'!AM10+'FED-PID(P)'!AM12,"") -> 7.501593 | AN10: =IFERROR('FED-PID(I)'!AN10+'FED-PID(K)'!AN10+'FED-PID(L)'!AN10+'FED-PID(P)'!AN12,"") -> 21.037137 | AO10: =IFERROR('FED-PID(I)'!AO10+'FED-PID(K)'!AO10+'FED-PID(L)'!AO10+'FED-PID(P)'!AO12,"") -> 15.581197 | AP10: =IFERROR('FED-PID(I)'!AP10+'FED-PID(K)'!AP10+'FED-PID(L)'!AP10+'FED-PID(P)'!AP12,"") -> 25.115278 | AQ10: =IFERROR('FED-PID(I)'!AQ10+'FED-PID(K)'!AQ10+'FED-PID(L)'!AQ10+'FED-PID(P)'!AQ12,"") -> 17.02 | AR10: ='FED-PID(K)'!AR10+'FED-PID(L)'!AR10+'FED-PID(I)'!AR10+'FED-PID(P)'!AR12 -> 20.514891 | AS10: ='FED-PID(K)'!AS10+'FED-PID(L)'!AS10+'FED-PID(I)'!AS10+'FED-PID(P)'!AS12 -> 22.490855 | AT10: ='FED-PID(K)'!AT10+'FED-PID(L)'!AT10+'FED-PID(I)'!AT10+'FED-PID(P)'!AT12 -> 22.497475 | AU10: ='FED-PID(K)'!AU10+'FED-PID(L)'!AU10+'FED-PID(I)'!AU10+'FED-PID(P)'!AU12 -> 22.28 | AV10: ='FED-PID(K)'!AV10+'FED-PID(L)'!AV10+'FED-PID(I)'!AV10+'FED-PID(P)'!AV12 -> 16.759801 | AW10: ='FED-PID(K)'!AW10+'FED-PID(L)'!AW10+'FED-PID(I)'!AW10+'FED-PID(P)'!AW12 -> 22.623171 | AX10: ='FED-PID(K)'!AX10+'FED-PID(L)'!AX10+'FED-PID(I)'!AX10+'FED-PID(P)'!AX12 -> 18.876684 | AY10: ='FED-PID(K)'!AY10+'FED-PID(L)'!AY10+'FED-PID(I)'!AY10+'FED-PID(P)'!AY12 -> 22.743567 | ... BE10: ='FED-PID(K)'!BE10+'FED-PID(L)'!BE10+'FED-PID(I)'!BE10+'FED-PID(P)'!BE12 -> 2.634143 | BF10: =SUM(OFFSET(BF10,0,-1,):OFFSET(BF10,0,-8)) -> 164.2751
A11: % of Jang | B11: =IFERROR(B10/B7,"") -> 1.0700638 | C11: =IFERROR(C10/C7,"") -> 1.270094 | D11: =IFERROR(D10/D7,"") -> 1.0524781 | E11: =IFERROR(E10/E7,"") -> 2.2410714 | F11: =IFERROR(F10/F7,"") -> 1.0806265 | G11: =IFERROR(G10/G7,"") -> 1.2052955 | H11: =IFERROR(H10/H7,"") -> 1.277811 | I11: =IFERROR(I10/I7,"") -> 1.7791133 | ... BE11: =IFERROR(BE10/BE7,"") -> 0.46784246 | BF11: =IFERROR(BF10/BF7,0) -> 0.62260348
A12: Dunya %of Express | B12: =IFERROR(B9/B10,"") -> 0.46757235 | C12: =IFERROR(C9/C10,"") -> 0.53334398 | D12: =IFERROR(D9/D10,"") -> 0.57248384 | E12: =IFERROR(E9/E10,"") -> 0.53545817 | F12: =IFERROR(F9/F10,"") -> 0.34438251 | G12: =IFERROR(G9/G10,"") -> 0.5074673 | H12: =IFERROR(H9/H10,"") -> 0.5191782 | I12: =IFERROR(I9/I10,"") -> 0.41835617 | ... BF12: =IFERROR(BF9/BF10,"") -> 0.73329631
A13: % Market share | B13: =IFERROR(B10/(SUM(B7:B10)),"") -> 0.35339651 | C13: =IFERROR(C10/(SUM(C7:C10)),"") -> 0.34505124 | D13: =IFERROR(D10/(SUM(D7:D10)),"") -> 0.3108496 | E13: =IFERROR(E10/(SUM(E7:E10)),"") -> 0.39255552 | F13: =IFERROR(F10/(SUM(F7:F10)),"") -> 0.35966285 | G13: =IFERROR(G10/(SUM(G7:G10)),"") -> 0.33855168 | H13: =IFERROR(H10/(SUM(H7:H10)),"") -> 0.35837749 | I13: =IFERROR(I10/(SUM(I7:I10)),"") -> 0.39285589 | ... BE13: =IFERROR(BE10/(SUM(BE7:BE10)),"") -> 0.20591963 | BF13: =IFERROR(BF10/(SUM(BF7:BF10)),0) -> 0.26639495
A16: ENGLISH DAILIES
A17: Dawn | B17: =IFERROR('FED-PID(I)'!B17+'FED-PID(K)'!B17+'FED-PID(L)'!B17+'FED-PID(P)'!B17,"") -> 13.953834 | C17: =IFERROR('FED-PID(I)'!C17+'FED-PID(K)'!C17+'FED-PID(L)'!C17+'FED-PID(P)'!C17,"") -> 5.774404 | D17: =IFERROR('FED-PID(I)'!D17+'FED-PID(K)'!D17+'FED-PID(L)'!D17+'FED-PID(P)'!D17,"") -> 8.8 | E17: =IFERROR('FED-PID(I)'!E17+'FED-PID(K)'!E17+'FED-PID(L)'!E17+'FED-PID(P)'!E17,"") -> 4.1 | F17: =IFERROR('FED-PID(I)'!F17+'FED-PID(K)'!F17+'FED-PID(L)'!F17+'FED-PID(P)'!F17,"") -> 10.434895 | G17: =IFERROR('FED-PID(I)'!G17+'FED-PID(K)'!G17+'FED-PID(L)'!G17+'FED-PID(P)'!G17,"") -> 8.095361 | H17: =IFERROR('FED-PID(I)'!H17+'FED-PID(K)'!H17+'FED-PID(L)'!H17+'FED-PID(P)'!H17,"") -> 10.617011 | I17: =IFERROR('FED-PID(I)'!I17+'FED-PID(K)'!I17+'FED-PID(L)'!I17+'FED-PID(P)'!I17,"") -> 12.656381 | ... AI17: =IFERROR('FED-PID(I)'!AI17+'FED-PID(K)'!AI17+'FED-PID(L)'!AI17+'FED-PID(P)'!AI17,"") -> 13.45372 | AJ17: =IFERROR('FED-PID(I)'!AJ17+'FED-PID(K)'!AJ17+'FED-PID(L)'!AJ17+'FED-PID(P)'!AJ18,"") -> 13.494285 | AK17: =IFERROR('FED-PID(I)'!AK17+'FED-PID(K)'!AK17+'FED-PID(L)'!AK17+'FED-PID(P)'!AK18,"") -> 19.297869 | AL17: =IFERROR('FED-PID(I)'!AL17+'FED-PID(K)'!AL17+'FED-PID(L)'!AL17+'FED-PID(P)'!AL18,"") -> 11.934633 | AM17: =IFERROR('FED-PID(I)'!AM17+'FED-PID(K)'!AM17+'FED-PID(L)'!AM17+'FED-PID(P)'!AM18,"") -> 11.717035 | AN17: =IFERROR('FED-PID(I)'!AN17+'FED-PID(K)'!AN17+'FED-PID(L)'!AN17+'FED-PID(P)'!AN18,"") -> 17.873013 | AO17: =IFERROR('FED-PID(I)'!AO17+'FED-PID(K)'!AO17+'FED-PID(L)'!AO17+'FED-PID(P)'!AO18,"") -> 14.48414 | AP17: =IFERROR('FED-PID(I)'!AP17+'FED-PID(K)'!AP17+'FED-PID(L)'!AP17+'FED-PID(P)'!AP18,"") -> 20.910307 | AQ17: =IFERROR('FED-PID(I)'!AQ17+'FED-PID(K)'!AQ17+'FED-PID(L)'!AQ17+'FED-PID(P)'!AQ18,"") -> 18.8 | AR17: ='FED-PID(K)'!AR17+'FED-PID(L)'!AR17+'FED-PID(I)'!AR17+'FED-PID(P)'!AR18 -> 14.934142 | AS17: ='FED-PID(K)'!AS17+'FED-PID(L)'!AS17+'FED-PID(I)'!AS17+'FED-PID(P)'!AS18 -> 21.018687 | AT17: ='FED-PID(K)'!AT17+'FED-PID(L)'!AT17+'FED-PID(I)'!AT17+'FED-PID(P)'!AT18 -> 17.543929 | AU17: ='FED-PID(K)'!AU17+'FED-PID(L)'!AU17+'FED-PID(I)'!AU17+'FED-PID(P)'!AU18 -> 4.836157 | AV17: ='FED-PID(K)'!AV17+'FED-PID(L)'!AV17+'FED-PID(I)'!AV17+'FED-PID(P)'!AV18 -> 0.660769 | AW17: ='FED-PID(K)'!AW17+'FED-PID(L)'!AW17+'FED-PID(I)'!AW17+'FED-PID(P)'!AW18 -> 0.612833 | AX17: ='FED-PID(K)'!AX17+'FED-PID(L)'!AX17+'FED-PID(I)'!AX17+'FED-PID(P)'!AX18 -> 0.77354 | AY17: ='FED-PID(K)'!AY17+'FED-PID(L)'!AY17+'FED-PID(I)'!AY17+'FED-PID(P)'!AY18 -> 0.796294 | ... BE17: ='FED-PID(K)'!BE17+'FED-PID(L)'!BE17+'FED-PID(I)'!BE17+'FED-PID(P)'!BE18 -> 0.225144 | BF17: =SUM(OFFSET(BF17,0,-1,):OFFSET(BF17,0,-8)) -> 11.400376
A18: The News | B18: =IFERROR('FED-PID(I)'!B18+'FED-PID(K)'!B18+'FED-PID(L)'!B18+'FED-PID(P)'!B18,"") -> 6.321294 | C18: =IFERROR('FED-PID(I)'!C18+'FED-PID(K)'!C18+'FED-PID(L)'!C18+'FED-PID(P)'!C18,"") -> 5.140003 | D18: =IFERROR('FED-PID(I)'!D18+'FED-PID(K)'!D18+'FED-PID(L)'!D18+'FED-PID(P)'!D18,"") -> 5.4 | E18: =IFERROR('FED-PID(I)'!E18+'FED-PID(K)'!E18+'FED-PID(L)'!E18+'FED-PID(P)'!E18,"") -> 3.09 | F18: =IFERROR('FED-PID(I)'!F18+'FED-PID(K)'!F18+'FED-PID(L)'!F18+'FED-PID(P)'!F18,"") -> 7.647306 | G18: =IFERROR('FED-PID(I)'!G18+'FED-PID(K)'!G18+'FED-PID(L)'!G18+'FED-PID(P)'!G18,"") -> 7.129734 | H18: =IFERROR('FED-PID(I)'!H18+'FED-PID(K)'!H18+'FED-PID(L)'!H18+'FED-PID(P)'!H18,"") -> 7.482154 | I18: =IFERROR('FED-PID(I)'!I18+'FED-PID(K)'!I18+'FED-PID(L)'!I18+'FED-PID(P)'!I18,"") -> 5.278454 | ... AI18: =IFERROR('FED-PID(I)'!AI18+'FED-PID(K)'!AI18+'FED-PID(L)'!AI18+'FED-PID(P)'!AI18,"") -> 9.801896 | AJ18: =IFERROR('FED-PID(I)'!AJ18+'FED-PID(K)'!AJ18+'FED-PID(L)'!AJ18+'FED-PID(P)'!AJ19,"") -> 9.390324 | AK18: =IFERROR('FED-PID(I)'!AK18+'FED-PID(K)'!AK18+'FED-PID(L)'!AK18+'FED-PID(P)'!AK19,"") -> 10.422133 | AL18: =IFERROR('FED-PID(I)'!AL18+'FED-PID(K)'!AL18+'FED-PID(L)'!AL18+'FED-PID(P)'!AL19,"") -> 9.195183 | AM18: =IFERROR('FED-PID(I)'!AM18+'FED-PID(K)'!AM18+'FED-PID(L)'!AM18+'FED-PID(P)'!AM19,"") -> 7.697813 | AN18: =IFERROR('FED-PID(I)'!AN18+'FED-PID(K)'!AN18+'FED-PID(L)'!AN18+'FED-PID(P)'!AN19,"") -> 12.753145 | AO18: =IFERROR('FED-PID(I)'!AO18+'FED-PID(K)'!AO18+'FED-PID(L)'!AO18+'FED-PID(P)'!AO19,"") -> 9.905656 | AP18: =IFERROR('FED-PID(I)'!AP18+'FED-PID(K)'!AP18+'FED-PID(L)'!AP18+'FED-PID(P)'!AP19,"") -> 18.838056 | AQ18: =IFERROR('FED-PID(I)'!AQ18+'FED-PID(K)'!AQ18+'FED-PID(L)'!AQ18+'FED-PID(P)'!AQ19,"") -> 15.447578 | AR18: ='FED-PID(K)'!AR18+'FED-PID(L)'!AR18+'FED-PID(I)'!AR18+'FED-PID(P)'!AR19 -> 14.927998 | AS18: ='FED-PID(K)'!AS18+'FED-PID(L)'!AS18+'FED-PID(I)'!AS18+'FED-PID(P)'!AS19 -> 15.958171 | AT18: ='FED-PID(K)'!AT18+'FED-PID(L)'!AT18+'FED-PID(I)'!AT18+'FED-PID(P)'!AT19 -> 15.948729 | AU18: ='FED-PID(K)'!AU18+'FED-PID(L)'!AU18+'FED-PID(I)'!AU18+'FED-PID(P)'!AU19 -> 18.17 | AV18: ='FED-PID(K)'!AV18+'FED-PID(L)'!AV18+'FED-PID(I)'!AV18+'FED-PID(P)'!AV19 -> 20.977438 | AW18: ='FED-PID(K)'!AW18+'FED-PID(L)'!AW18+'FED-PID(I)'!AW18+'FED-PID(P)'!AW19 -> 26.001867 | AX18: ='FED-PID(K)'!AX18+'FED-PID(L)'!AX18+'FED-PID(I)'!AX18+'FED-PID(P)'!AX19 -> 21.650404 | AY18: ='FED-PID(K)'!AY18+'FED-PID(L)'!AY18+'FED-PID(I)'!AY18+'FED-PID(P)'!AY19 -> 22.920893 | ... BE18: ='FED-PID(K)'!BE18+'FED-PID(L)'!BE18+'FED-PID(I)'!BE18+'FED-PID(P)'!BE19 -> 4.175872 | BF18: =SUM(OFFSET(BF18,0,-1,):OFFSET(BF18,0,-8)) -> 161.62663
A19: The Nation | B19: =IFERROR('FED-PID(I)'!B19+'FED-PID(K)'!B19+'FED-PID(L)'!B19+'FED-PID(P)'!B19,"") -> 3.997251 | C19: =IFERROR('FED-PID(I)'!C19+'FED-PID(K)'!C19+'FED-PID(L)'!C19+'FED-PID(P)'!C19,"") -> 3.925002 | D19: =IFERROR('FED-PID(I)'!D19+'FED-PID(K)'!D19+'FED-PID(L)'!D19+'FED-PID(P)'!D19,"") -> 5.08 | E19: =IFERROR('FED-PID(I)'!E19+'FED-PID(K)'!E19+'FED-PID(L)'!E19+'FED-PID(P)'!E19,"") -> 4.92 | F19: =IFERROR('FED-PID(I)'!F19+'FED-PID(K)'!F19+'FED-PID(L)'!F19+'FED-PID(P)'!F19,"") -> 4.26907 | G19: =IFERROR('FED-PID(I)'!G19+'FED-PID(K)'!G19+'FED-PID(L)'!G19+'FED-PID(P)'!G19,"") -> 3.036998 | H19: =IFERROR('FED-PID(I)'!H19+'FED-PID(K)'!H19+'FED-PID(L)'!H19+'FED-PID(P)'!H19,"") -> 4.341037 | I19: =IFERROR('FED-PID(I)'!I19+'FED-PID(K)'!I19+'FED-PID(L)'!I19+'FED-PID(P)'!I19,"") -> 5.448661 | ... AI19: =IFERROR('FED-PID(I)'!AI19+'FED-PID(K)'!AI19+'FED-PID(L)'!AI19+'FED-PID(P)'!AI19,"") -> 3.193904 | AJ19: =IFERROR('FED-PID(I)'!AJ19+'FED-PID(K)'!AJ19+'FED-PID(L)'!AJ19+'FED-PID(P)'!AJ20,"") -> 3.893676 | AK19: =IFERROR('FED-PID(I)'!AK19+'FED-PID(K)'!AK19+'FED-PID(L)'!AK19+'FED-PID(P)'!AK20,"") -> 3.826207 | AL19: =IFERROR('FED-PID(I)'!AL19+'FED-PID(K)'!AL19+'FED-PID(L)'!AL19+'FED-PID(P)'!AL20,"") -> 3.005638 | AM19: =IFERROR('FED-PID(I)'!AM19+'FED-PID(K)'!AM19+'FED-PID(L)'!AM19+'FED-PID(P)'!AM20,"") -> 2.330532 | AN19: =IFERROR('FED-PID(I)'!AN19+'FED-PID(K)'!AN19+'FED-PID(L)'!AN19+'FED-PID(P)'!AN20,"") -> 5.126404 | AO19: =IFERROR('FED-PID(I)'!AO19+'FED-PID(K)'!AO19+'FED-PID(L)'!AO19+'FED-PID(P)'!AO20,"") -> 2.89823 | AP19: =IFERROR('FED-PID(I)'!AP19+'FED-PID(K)'!AP19+'FED-PID(L)'!AP19+'FED-PID(P)'!AP20,"") -> 5.661383 | AQ19: =IFERROR('FED-PID(I)'!AQ19+'FED-PID(K)'!AQ19+'FED-PID(L)'!AQ19+'FED-PID(P)'!AQ20,"") -> 3.91 | AR19: ='FED-PID(K)'!AR19+'FED-PID(L)'!AR19+'FED-PID(I)'!AR19+'FED-PID(P)'!AR20 -> 5.143997 | AS19: ='FED-PID(K)'!AS19+'FED-PID(L)'!AS19+'FED-PID(I)'!AS19+'FED-PID(P)'!AS20 -> 5.539189 | AT19: ='FED-PID(K)'!AT19+'FED-PID(L)'!AT19+'FED-PID(I)'!AT19+'FED-PID(P)'!AT20 -> 3.406566 | AU19: ='FED-PID(K)'!AU19+'FED-PID(L)'!AU19+'FED-PID(I)'!AU19+'FED-PID(P)'!AU20 -> 6.27 | AV19: ='FED-PID(K)'!AV19+'FED-PID(L)'!AV19+'FED-PID(I)'!AV19+'FED-PID(P)'!AV20 -> 5.417564 | AW19: ='FED-PID(K)'!AW19+'FED-PID(L)'!AW19+'FED-PID(I)'!AW19+'FED-PID(P)'!AW20 -> 7.698912 | AX19: ='FED-PID(K)'!AX19+'FED-PID(L)'!AX19+'FED-PID(I)'!AX19+'FED-PID(P)'!AX20 -> 7.481513 | AY19: ='FED-PID(K)'!AY19+'FED-PID(L)'!AY19+'FED-PID(I)'!AY19+'FED-PID(P)'!AY20 -> 7.314668 | ... BE19: ='FED-PID(K)'!BE19+'FED-PID(L)'!BE19+'FED-PID(I)'!BE19+'FED-PID(P)'!BE20 -> 0.563153 | BF19: =SUM(OFFSET(BF19,0,-1,):OFFSET(BF19,0,-8)) -> 44.64436
A20: Express Tribune | B20: =IFERROR('FED-PID(I)'!B20+'FED-PID(K)'!B20+'FED-PID(L)'!B20+'FED-PID(P)'!B20,"") -> 5.799375 | C20: =IFERROR('FED-PID(I)'!C20+'FED-PID(K)'!C20+'FED-PID(L)'!C20+'FED-PID(P)'!C20,"") -> 3.745056 | D20: =IFERROR('FED-PID(I)'!D20+'FED-PID(K)'!D20+'FED-PID(L)'!D20+'FED-PID(P)'!D20,"") -> 6.36 | E20: =IFERROR('FED-PID(I)'!E20+'FED-PID(K)'!E20+'FED-PID(L)'!E20+'FED-PID(P)'!E20,"") -> 5.36 | F20: =IFERROR('FED-PID(I)'!F20+'FED-PID(K)'!F20+'FED-PID(L)'!F20+'FED-PID(P)'!F20,"") -> 5.565965 | G20: =IFERROR('FED-PID(I)'!G20+'FED-PID(K)'!G20+'FED-PID(L)'!G20+'FED-PID(P)'!G20,"") -> 5.442742 | H20: =IFERROR('FED-PID(I)'!H20+'FED-PID(K)'!H20+'FED-PID(L)'!H20+'FED-PID(P)'!H20,"") -> 6.232913 | I20: =IFERROR('FED-PID(I)'!I20+'FED-PID(K)'!I20+'FED-PID(L)'!I20+'FED-PID(P)'!I20,"") -> 9.343403 | ... AI20: =IFERROR('FED-PID(I)'!AI20+'FED-PID(K)'!AI20+'FED-PID(L)'!AI20+'FED-PID(P)'!AI20,"") -> 6.641864 | AJ20: =IFERROR('FED-PID(I)'!AJ20+'FED-PID(K)'!AJ20+'FED-PID(L)'!AJ20+'FED-PID(P)'!AJ21,"") -> 7.056281 | AK20: =IFERROR('FED-PID(I)'!AK20+'FED-PID(K)'!AK20+'FED-PID(L)'!AK20+'FED-PID(P)'!AK21,"") -> 7.832696 | AL20: =IFERROR('FED-PID(I)'!AL20+'FED-PID(K)'!AL20+'FED-PID(L)'!AL20+'FED-PID(P)'!AL21,"") -> 5.95072 | AM20: =IFERROR('FED-PID(I)'!AM20+'FED-PID(K)'!AM20+'FED-PID(L)'!AM20+'FED-PID(P)'!AM21,"") -> 5.18032 | AN20: =IFERROR('FED-PID(I)'!AN20+'FED-PID(K)'!AN20+'FED-PID(L)'!AN20+'FED-PID(P)'!AN21,"") -> 8.428813 | AO20: =IFERROR('FED-PID(I)'!AO20+'FED-PID(K)'!AO20+'FED-PID(L)'!AO20+'FED-PID(P)'!AO21,"") -> 5.98236 | AP20: =IFERROR('FED-PID(I)'!AP20+'FED-PID(K)'!AP20+'FED-PID(L)'!AP20+'FED-PID(P)'!AP21,"") -> 10.996279 | AQ20: =IFERROR('FED-PID(I)'!AQ20+'FED-PID(K)'!AQ20+'FED-PID(L)'!AQ20+'FED-PID(P)'!AQ21,"") -> 9.2816 | AR20: ='FED-PID(K)'!AR20+'FED-PID(L)'!AR20+'FED-PID(I)'!AR20+'FED-PID(P)'!AR21 -> 9.915151 | AS20: ='FED-PID(K)'!AS20+'FED-PID(L)'!AS20+'FED-PID(I)'!AS20+'FED-PID(P)'!AS21 -> 11.142821 | AT20: ='FED-PID(K)'!AT20+'FED-PID(L)'!AT20+'FED-PID(I)'!AT20+'FED-PID(P)'!AT21 -> 9.9489 | AU20: ='FED-PID(K)'!AU20+'FED-PID(L)'!AU20+'FED-PID(I)'!AU20+'FED-PID(P)'!AU21 -> 12.07 | AV20: ='FED-PID(K)'!AV20+'FED-PID(L)'!AV20+'FED-PID(I)'!AV20+'FED-PID(P)'!AV21 -> 17.609058 | AW20: ='FED-PID(K)'!AW20+'FED-PID(L)'!AW20+'FED-PID(I)'!AW20+'FED-PID(P)'!AW21 -> 20.438233 | AX20: ='FED-PID(K)'!AX20+'FED-PID(L)'!AX20+'FED-PID(I)'!AX20+'FED-PID(P)'!AX21 -> 14.462521 | AY20: ='FED-PID(K)'!AY20+'FED-PID(L)'!AY20+'FED-PID(I)'!AY20+'FED-PID(P)'!AY21 -> 16.247897 | ... BE20: ='FED-PID(K)'!BE20+'FED-PID(L)'!BE20+'FED-PID(I)'!BE20+'FED-PID(P)'!BE21 -> 3.267511 | BF20: =SUM(OFFSET(BF20,0,-1,):OFFSET(BF20,0,-8)) -> 122.23411
A21: % of Dawn | B21: =IFERROR(B20/B17,"") -> 0.41561158 | C21: =IFERROR(C20/C17,"") -> 0.64856148 | D21: =IFERROR(D20/D17,"") -> 0.72272727 | E21: =IFERROR(E20/E17,"") -> 1.3073171 | F21: =IFERROR(F20/F17,"") -> 0.53339923 | G21: =IFERROR(G20/G17,"") -> 0.67232851 | H21: =IFERROR(H20/H17,"") -> 0.58706853 | I21: =IFERROR(I20/I17,"") -> 0.73823655 | ... BF21: =IFERROR(BF20/BF17,"") -> 10.721937
A22: % of News | B22: =IFERROR(B20/B18,"") -> 0.91743478 | C22: =IFERROR(C20/C18,"") -> 0.72860969 | D22: =IFERROR(D20/D18,"") -> 1.1777778 | E22: =IFERROR(E20/E18,"") -> 1.7346278 | F22: =IFERROR(F20/F18,"") -> 0.72783344 | G22: =IFERROR(G20/G18,"") -> 0.7633864 | H22: =IFERROR(H20/H18,"") -> 0.83303725 | I22: =IFERROR(I20/I18,"") -> 1.7701022 | ... BF22: =IFERROR(BF20/BF18,"") -> 0.75627456
A23: % Market share | B23: =IFERROR(B20/(SUM(B17:B20)),"") -> 0.19285124 | C23: =IFERROR(C20/(SUM(C17:C20)),"") -> 0.20151541 | D23: =IFERROR(D20/(SUM(D17:D20)),"") -> 0.24804992 | E23: =IFERROR(E20/(SUM(E17:E20)),"") -> 0.30681168 | F23: =IFERROR(F20/(SUM(F17:F20)),"") -> 0.19937378 | G23: =IFERROR(G20/(SUM(G17:G20)),"") -> 0.22960472 | H23: =IFERROR(H20/(SUM(H17:H20)),"") -> 0.2173783 | I23: =IFERROR(I20/(SUM(I17:I20)),"") -> 0.28549613 | ... BF23: =IFERROR(BF20/(SUM(BF17:BF20)),"") -> 0.35961206
A26: SINDHI DAILIES
A27: Kawish | B27: =IFERROR('FED-PID(I)'!B27+'FED-PID(K)'!B27+'FED-PID(L)'!B27+'FED-PID(P)'!B27,"") -> 1.795784 | C27: =IFERROR('FED-PID(I)'!C27+'FED-PID(K)'!C27+'FED-PID(L)'!C27+'FED-PID(P)'!C27,"") -> 1.121685 | D27: =IFERROR('FED-PID(I)'!D27+'FED-PID(K)'!D27+'FED-PID(L)'!D27+'FED-PID(P)'!D27,"") -> 1.5 | E27: =IFERROR('FED-PID(I)'!E27+'FED-PID(K)'!E27+'FED-PID(L)'!E27+'FED-PID(P)'!E27,"") -> 1.31 | F27: =IFERROR('FED-PID(I)'!F27+'FED-PID(K)'!F27+'FED-PID(L)'!F27+'FED-PID(P)'!F27,"") -> 1.396854 | G27: =IFERROR('FED-PID(I)'!G27+'FED-PID(K)'!G27+'FED-PID(L)'!G27+'FED-PID(P)'!G27,"") -> 1.034401 | H27: =IFERROR('FED-PID(I)'!H27+'FED-PID(K)'!H27+'FED-PID(L)'!H27+'FED-PID(P)'!H27,"") -> 1.572873 | I27: =IFERROR('FED-PID(I)'!I27+'FED-PID(K)'!I27+'FED-PID(L)'!I27+'FED-PID(P)'!I27,"") -> 1.680217 | ... AQ27: =IFERROR('FED-PID(I)'!AQ27+'FED-PID(K)'!AQ27+'FED-PID(L)'!AQ27+'FED-PID(P)'!AQ27,"") -> 2.04 | AR27: ='FED-PID(K)'!AR27+'FED-PID(I)'!AR27 -> 1.221911 | AS27: ='FED-PID(K)'!AS27+'FED-PID(I)'!AS27 -> 2.074997 | AT27: ='FED-PID(K)'!AT27+'FED-PID(I)'!AT27 -> 1.903708 | AU27: ='FED-PID(K)'!AU27+'FED-PID(I)'!AU27 -> 1.870981 | AV27: ='FED-PID(K)'!AV27+'FED-PID(I)'!AV27 -> 1.559531 | AW27: ='FED-PID(K)'!AW27+'FED-PID(I)'!AW27 -> 1.431195 | AX27: ='FED-PID(K)'!AX27+'FED-PID(I)'!AX27 -> 1.241507 | AY27: ='FED-PID(K)'!AY27+'FED-PID(I)'!AY27 -> 2.56405 | ... BE27: ='FED-PID(K)'!BE27+'FED-PID(I)'!BE27 -> 0.734532 | BF27: =SUM(OFFSET(BF27,0,-1,):OFFSET(BF27,0,-8)) -> 17.824488
A28: Ibrat | B28: =IFERROR('FED-PID(I)'!B28+'FED-PID(K)'!B28+'FED-PID(L)'!B28+'FED-PID(P)'!B28,"") -> 0.502075 | C28: =IFERROR('FED-PID(I)'!C28+'FED-PID(K)'!C28+'FED-PID(L)'!C28+'FED-PID(P)'!C28,"") -> 0.851532 | D28: =IFERROR('FED-PID(I)'!D28+'FED-PID(K)'!D28+'FED-PID(L)'!D28+'FED-PID(P)'!D28,"") -> 0.29 | E28: =IFERROR('FED-PID(I)'!E28+'FED-PID(K)'!E28+'FED-PID(L)'!E28+'FED-PID(P)'!E28,"") -> 1.09 | F28: =IFERROR('FED-PID(I)'!F28+'FED-PID(K)'!F28+'FED-PID(L)'!F28+'FED-PID(P)'!F28,"") -> 1.86303 | G28: =IFERROR('FED-PID(I)'!G28+'FED-PID(K)'!G28+'FED-PID(L)'!G28+'FED-PID(P)'!G28,"") -> 0.632345 | H28: =IFERROR('FED-PID(I)'!H28+'FED-PID(K)'!H28+'FED-PID(L)'!H28+'FED-PID(P)'!H28,"") -> 1.745078 | I28: =IFERROR('FED-PID(I)'!I28+'FED-PID(K)'!I28+'FED-PID(L)'!I28+'FED-PID(P)'!I28,"") -> 0.623969 | ... AQ28: =IFERROR('FED-PID(I)'!AQ28+'FED-PID(K)'!AQ28+'FED-PID(L)'!AQ28+'FED-PID(P)'!AQ28,"") -> 0.563754 | AR28: ='FED-PID(K)'!AR28+'FED-PID(I)'!AR28 -> 0.794496 | AS28: ='FED-PID(K)'!AS28+'FED-PID(I)'!AS28 -> 0.890258 | AT28: ='FED-PID(K)'!AT28+'FED-PID(I)'!AT28 -> 1.377978 | AU28: ='FED-PID(K)'!AU28+'FED-PID(I)'!AU28 -> 0.76134 | AV28: ='FED-PID(K)'!AV28+'FED-PID(I)'!AV28 -> 0.667587 | AW28: ='FED-PID(K)'!AW28+'FED-PID(I)'!AW28 -> 1.002097 | AX28: ='FED-PID(K)'!AX28+'FED-PID(I)'!AX28 -> 1.129433 | AY28: ='FED-PID(K)'!AY28+'FED-PID(I)'!AY28 -> 1.742804 | ... BE28: ='FED-PID(K)'!BE28+'FED-PID(I)'!BE28 -> 0.456867 | BF28: =SUM(OFFSET(BF28,0,-1,):OFFSET(BF28,0,-8)) -> 12.418394
A29: Awami Awaz | B29: =IFERROR('FED-PID(I)'!B29+'FED-PID(K)'!B29+'FED-PID(L)'!B29+'FED-PID(P)'!B29,"") -> 0.774476 | C29: =IFERROR('FED-PID(I)'!C29+'FED-PID(K)'!C29+'FED-PID(L)'!C29+'FED-PID(P)'!C29,"") -> 0.651834 | D29: =IFERROR('FED-PID(I)'!D29+'FED-PID(K)'!D29+'FED-PID(L)'!D29+'FED-PID(P)'!D29,"") -> 1.16 | E29: =IFERROR('FED-PID(I)'!E29+'FED-PID(K)'!E29+'FED-PID(L)'!E29+'FED-PID(P)'!E29,"") -> 0.73 | F29: =IFERROR('FED-PID(I)'!F29+'FED-PID(K)'!F29+'FED-PID(L)'!F29+'FED-PID(P)'!F29,"") -> 1.23831 | G29: =IFERROR('FED-PID(I)'!G29+'FED-PID(K)'!G29+'FED-PID(L)'!G29+'FED-PID(P)'!G29,"") -> 0.53944 | H29: =IFERROR('FED-PID(I)'!H29+'FED-PID(K)'!H29+'FED-PID(L)'!H29+'FED-PID(P)'!H29,"") -> 0.913738 | I29: =IFERROR('FED-PID(I)'!I29+'FED-PID(K)'!I29+'FED-PID(L)'!I29+'FED-PID(P)'!I29,"") -> 1.727157 | ... AQ29: =IFERROR('FED-PID(I)'!AQ29+'FED-PID(K)'!AQ29+'FED-PID(L)'!AQ29+'FED-PID(P)'!AQ29,"") -> 0.98 | AR29: ='FED-PID(K)'!AR29+'FED-PID(I)'!AR29 -> 1.491683 | AS29: ='FED-PID(K)'!AS29+'FED-PID(I)'!AS29 -> 1.902558 | AT29: ='FED-PID(K)'!AT29+'FED-PID(I)'!AT29 -> 1.284131 | AU29: ='FED-PID(K)'!AU29+'FED-PID(I)'!AU29 -> 1.64 | AV29: ='FED-PID(K)'!AV29+'FED-PID(I)'!AV29 -> 1.470265 | AW29: ='FED-PID(K)'!AW29+'FED-PID(I)'!AW29 -> 1.441162 | AX29: ='FED-PID(K)'!AX29+'FED-PID(I)'!AX29 -> 1.357175 | AY29: ='FED-PID(K)'!AY29+'FED-PID(I)'!AY29 -> 1.183173 | ... BE29: ='FED-PID(K)'!BE29+'FED-PID(I)'!BE29 -> 0.429763 | BF29: =SUM(OFFSET(BF29,0,-1,):OFFSET(BF29,0,-8)) -> 9.917191
A30: Sobh | B30: =IFERROR('FED-PID(I)'!B30+'FED-PID(K)'!B30+'FED-PID(L)'!B30+'FED-PID(P)'!B30,"") -> 0 | C30: =IFERROR('FED-PID(I)'!C30+'FED-PID(K)'!C30+'FED-PID(L)'!C30+'FED-PID(P)'!C30,"") -> 0 | D30: =IFERROR('FED-PID(I)'!D30+'FED-PID(K)'!D30+'FED-PID(L)'!D30+'FED-PID(P)'!D30,"") -> 0 | E30: =IFERROR('FED-PID(I)'!E30+'FED-PID(K)'!E30+'FED-PID(L)'!E30+'FED-PID(P)'!E30,"") -> 0 | F30: =IFERROR('FED-PID(I)'!F30+'FED-PID(K)'!F30+'FED-PID(L)'!F30+'FED-PID(P)'!F30,"") -> 0 | G30: =IFERROR('FED-PID(I)'!G30+'FED-PID(K)'!G30+'FED-PID(L)'!G30+'FED-PID(P)'!G30,"") -> 0 | H30: =IFERROR('FED-PID(I)'!H30+'FED-PID(K)'!H30+'FED-PID(L)'!H30+'FED-PID(P)'!H30,"") -> 0 | I30: =IFERROR('FED-PID(I)'!I30+'FED-PID(K)'!I30+'FED-PID(L)'!I30+'FED-PID(P)'!I30,"") -> 0 | ... AQ30: =IFERROR('FED-PID(I)'!AQ30+'FED-PID(K)'!AQ30+'FED-PID(L)'!AQ30+'FED-PID(P)'!AQ30,"") -> 0 | BF30: =SUM(OFFSET(BF30,0,-1,):OFFSET(BF30,0,-8)) -> 0
A31: Sindh Express | B31: =IFERROR('FED-PID(I)'!B31+'FED-PID(K)'!B31+'FED-PID(L)'!B31+'FED-PID(P)'!B31,"") -> 0.20073 | C31: =IFERROR('FED-PID(I)'!C31+'FED-PID(K)'!C31+'FED-PID(L)'!C31+'FED-PID(P)'!C31,"") -> 0.175356 | D31: =IFERROR('FED-PID(I)'!D31+'FED-PID(K)'!D31+'FED-PID(L)'!D31+'FED-PID(P)'!D31,"") -> 0.32 | E31: =IFERROR('FED-PID(I)'!E31+'FED-PID(K)'!E31+'FED-PID(L)'!E31+'FED-PID(P)'!E31,"") -> 0.12 | F31: =IFERROR('FED-PID(I)'!F31+'FED-PID(K)'!F31+'FED-PID(L)'!F31+'FED-PID(P)'!F31,"") -> 0.345416 | G31: =IFERROR('FED-PID(I)'!G31+'FED-PID(K)'!G31+'FED-PID(L)'!G31+'FED-PID(P)'!G31,"") -> 0.202884 | H31: =IFERROR('FED-PID(I)'!H31+'FED-PID(K)'!H31+'FED-PID(L)'!H31+'FED-PID(P)'!H31,"") -> 0.640307 | I31: =IFERROR('FED-PID(I)'!I31+'FED-PID(K)'!I31+'FED-PID(L)'!I31+'FED-PID(P)'!I31,"") -> 0.781495 | ... AQ31: =IFERROR('FED-PID(I)'!AQ31+'FED-PID(K)'!AQ31+'FED-PID(L)'!AQ31+'FED-PID(P)'!AQ31,"") -> 0.55 | AR31: ='FED-PID(K)'!AR31+'FED-PID(I)'!AR31 -> 0.602059 | AS31: ='FED-PID(K)'!AS31+'FED-PID(I)'!AS31 -> 1.193619 | AT31: ='FED-PID(K)'!AT31+'FED-PID(I)'!AT31 -> 0.080139 | AU31: ='FED-PID(K)'!AU31+'FED-PID(I)'!AU31 -> 0.54 | AV31: ='FED-PID(K)'!AV31+'FED-PID(I)'!AV31 -> 0.083183 | AW31: ='FED-PID(K)'!AW31+'FED-PID(I)'!AW31 -> 0.36722 | AX31: ='FED-PID(K)'!AX31+'FED-PID(I)'!AX31 -> 0.116659 | AY31: ='FED-PID(K)'!AY31+'FED-PID(I)'!AY31 -> 0.141005 | ... BE31: ='FED-PID(K)'!BE31+'FED-PID(I)'!BE31 -> 0.083182 | BF31: =SUM(OFFSET(BF31,0,-1,):OFFSET(BF31,0,-8)) -> 1.606232
A32: % of Kawish | B32: =IFERROR(B31/B27,"") -> 0.11177848 | C32: =IFERROR(C31/C27,"") -> 0.15633266 | D32: =IFERROR(D31/D27,"") -> 0.21333333 | E32: =IFERROR(E31/E27,"") -> 0.091603053 | F32: =IFERROR(F31/F27,"") -> 0.24728139 | G32: =IFERROR(G31/G27,"") -> 0.1961367 | H32: =IFERROR(H31/H27,"") -> 0.4070939 | I32: =IFERROR(I31/I27,"") -> 0.46511552 | ... BF32: =IFERROR(BF31/BF27,"") -> 0.090113781
A33: % Market share | B33: =IFERROR(B31/(SUM(B27:B31)),"") -> 0.061327838 | C33: =IFERROR(C31/(SUM(C27:C31)),"") -> 0.062618041 | D33: =IFERROR(D31/(SUM(D27:D31)),"") -> 0.097859327 | E33: =IFERROR(E31/(SUM(E27:E31)),"") -> 0.036923077 | F33: =IFERROR(F31/(SUM(F27:F31)),"") -> 0.071313752 | G33: =IFERROR(G31/(SUM(G27:G31)),"") -> 0.084216731 | H33: =IFERROR(H31/(SUM(H27:H31)),"") -> 0.13142601 | I33: =IFERROR(I31/(SUM(I27:I31)),"") -> 0.16237717 | ... BF33: =IFERROR(BF31/(SUM(BF27:BF31)),"") -> 0.038457604
A35: Grading
A36: Total /Highest
A37: Medium (50% of Total)
A38: Lowest
A66: urdu
A67: JAN'15
A68: FEB'15
A69: MAR'15
A70: APR'15
A71: MAY'15
A72: JUN'15
A73: JULY'15
...

Sheet FED-PID(K)
A1: Karachi PIDs Revenues (Federal Government)
A2: From 01/01/2021 To 05/8/2025
A4: Rs in million
B5: Jan'21 | C5: Feb'21 | D5: Mar'21 | E5: Apr'21 | F5: May'21 | G5: Jun'21 | H5: Jul'21 | I5: Aug'21 | J5: Sep'21 | K5: Oct'21 | L5: Nov'21 | M5: Dec'21 | N5: Jan'22 | O5: Feb'22 | P5: Mar'22 | Q5: Apr'22 | R5: May'22 | S5: Jun'22 | T5: Jul'22 | U5: Aug'22 | V5: Sep'22 | W5: Oct'22 | X5: Nov'22 | Y5: Dec'22 | Z5: Jan'23 | AA5: Feb'23 | AB5: Mar'23 | AC5: Apr'23 | AD5: May'23 | AE5: Jun'23 | AF5: Jul'23 | AG5: Aug'23 | AH5: Sep'23 | AI5: Oct'23 | AJ5: Nov'23 | AK5: Dec'23 | AL5: Jan'24 | AM5: Feb'24 | AN5: Mar'24 | AO5: Apr'24 | AP5: May'24 | AQ5: Jun'24 | AR5: ='FED-PID(ALL)'!AR5 -> Jul'24 | AS5: ='FED-PID(ALL)'!AS5 -> Aug'24 | AT5: ='FED-PID(ALL)'!AT5 -> Sep'24 | AU5: ='FED-PID(ALL)'!AU5 -> Oct'24 | AV5: ='FED-PID(ALL)'!AV5 -> Nov'24 | AW5: ='FED-PID(ALL)'!AW5 -> Dec'24 | AX5: ='FED-PID(ALL)'!AX5 -> Jan'25 | AY5: ='FED-PID(ALL)'!AY5 -> Feb'25 | ... BD5: ='FED-PID(ALL)'!BD5 -> Jul'25 | BE5: 1-5-Aug'25 | BF5: TOTAL
A6: URDU DAILIES
A7: Jang | B7: 1.856006 | C7: 1.325413 | D7: 2.6 | E7: 1.4 | F7: 2.495543 | G7: 2.545543 | H7: 1.982599 | I7: 2.235739 | J7: 1.937301 | K7: 1.999335 | L7: 3.802504 | M7: 4.623924 | N7: 2.973394 | O7: 2.413815 | P7: 0.338193 | Q7: 0.687754 | R7: 3.965255 | S7: 3.168266 | T7: 2.2013 | U7: 4.336935 | V7: 4.052489 | W7: 4.021154 | X7: 6.009009 | Y7: 3.893744 | Z7: 3.546741 | AA7: 2.811452 | AB7: 2.871886 | AC7: 2.937747 | AD7: 2.925448 | AE7: 3.4201 | AF7: 3.950893 | AG7: 4.421612 | AH7: 4.1 | AI7: 2.616394 | AJ7: 3.781798 | AK7: 8.19904 | AL7: 2.086557 | AM7: 3.320299 | AN7: 6.94 | AO7: 3.991557 | AP7: 4.420787 | AQ7: 5.61 | AR7: 3.357137 | AS7: 5.892568 | AT7: 6.042455 | AU7: 3.58 | AV7: 7.093067 | AW7: 6.722383 | AX7: 3.459861 | AY7: 3.007713 | AZ7: 4.701196 | BA7: 3.59 | BB7: 6.07 | BC7: 6.39 | BD7: 6.87 | BE7: 1.569506 | BF7: =SUM(OFFSET(BF7,0,-1,):OFFSET(BF7,0,-8)) -> 35.658276
A8: Nawa-e-Waqt | B8: 1.002764 | C8: 1.325413 | D8: 1.6 | E8: 0.9 | F8: 0.735711 | G8: 0.689371 | H8: 0.559737 | I8: 0.874119 | J8: 0.673927 | K8: 0.543214 | L8: 0.610018 | M8: 0.978761 | N8: 0.636849 | O8: 0.655352 | P8: 0.822158 | Q8: 0.497116 | R8: 0.756809 | S8: 0.85491 | T8: 0.620546 | U8: 0.826327 | V8: 1.293032 | W8: 0.948287 | X8: 1.183978 | Y8: 1.204828 | Z8: 0.696332 | AA8: 0.816224 | AB8: 0.76681 | AC8: 0.540901 | AD8: 0.692934 | AE8: 0.655273 | AF8: 0.778123 | AG8: 1.256872 | AH8: 0.52 | AI8: 1.135776 | AJ8: 0.539948 | AK8: 1.220431 | AL8: 0.387187 | AM8: 0.462088 | AN8: 0.77 | AO8: 0.484625 | AP8: 0.657284 | AQ8: 0.81 | AR8: 0.603592 | AS8: 1.279589 | AT8: 0.608363 | AU8: 0.64 | AV8: 1.062696 | AW8: 1.98864 | AX8: 0.615414 | AY8: 0.831783 | AZ8: 1.069268 | BA8: 0.71 | BB8: 1.42 | BC8: 1.25 | BD8: 0.98 | BE8: 0.234367 | BF8: =SUM(OFFSET(BF8,0,-1,):OFFSET(BF8,0,-8)) -> 7.110832
A9: Dunya | B9: 1.177694 | C9: 0.753044 | D9: 1.6 | E9: 1.5 | F9: 0.639837 | G9: 1.297196 | H9: 0.27434 | I9: 1.102437 | J9: 0.604818 | K9: 0.701474 | L9: 0.45673 | M9: 1.510972 | N9: 1.792546 | O9: 1.448701 | P9: 2.786599 | Q9: 1.494241 | R9: 1.552658 | S9: 1.929922 | T9: 1.004421 | U9: 1.436887 | V9: 1.717239 | W9: 1.436805 | X9: 2.31635 | Y9: 1.495633 | Z9: 1.826183 | AA9: 1.269228 | AB9: 1.527613 | AC9: 1.244758 | AD9: 1.540483 | AE9: 1.569819 | AF9: 1.688772 | AG9: 1.752557 | AH9: 1.56 | AI9: 0.710741 | AJ9: 1.540929 | AK9: 1.516655 | AL9: 0.720556 | AM9: 0.977985 | AN9: 1.54 | AO9: 1.301966 | AP9: 1.220905 | AQ9: 1.33 | AR9: 1.112697 | AS9: 1.018256 | AT9: 2.253056 | AU9: 1.25 | AV9: 2.062227 | AW9: 1.59999 | AX9: 1.3082 | AY9: 1.369598 | AZ9: 1.635674 | BA9: 1.33 | BB9: 1.36 | BC9: 1.92 | BD9: 2.29 | BE9: 0.383548 | BF9: =SUM(OFFSET(BF9,0,-1,):OFFSET(BF9,0,-8)) -> 11.59702
A10: Express | B10: 2.774099 | C10: 1.598019 | D10: 2.6 | E10: 1.8 | F10: 1.986884 | G10: 1.758644 | H10: 1.959274 | I10: 3.196627 | J10: 2.860109 | K10: 2.97819 | L10: 2.190761 | M10: 2.256433 | N10: 1.372475 | O10: 1.615479 | P10: 3.564576 | Q10: 2.459789 | R10: 2.814043 | S10: 2.258772 | T10: 1.232248 | U10: 2.492531 | V10: 3.729916 | W10: 1.895998 | X10: 3.83061 | Y10: 3.134008 | Z10: 1.894208 | AA10: 1.429838 | AB10: 1.620863 | AC10: 1.458777 | AD10: 1.147832 | AE10: 2.253635 | AF10: 1.892758 | AG10: 2.43894 | AH10: 2.12 | AI10: 1.473145 | AJ10: 1.035718 | AK10: 3.377635 | AL10: 1.400159 | AM10: 1.05911 | AN10: 3.31 | AO10: 2.163398 | AP10: 2.143852 | AQ10: 1.99 | AR10: 2.398634 | AS10: 2.244596 | AT10: 3.624204 | AU10: 1.51 | AV10: 2.499056 | AW10: 2.553783 | AX10: 1.767891 | AY10: 1.777008 | AZ10: 2.340023 | BA10: 1.4 | BB10: 2.41 | BC10: 2.87 | BD10: 2.43 | BE10: 0.466954 | BF10: =SUM(OFFSET(BF10,0,-1,):OFFSET(BF10,0,-8)) -> 15.461876
A11: % of Jang | B11: =IFERROR(B10/B7,"") -> 1.4946606 | C11: =IFERROR(C10/C7,"") -> 1.2056763 | D11: =IFERROR(D10/D7,"") -> 1 | E11: =IFERROR(E10/E7,"") -> 1.2857143 | F11: =IFERROR(F10/F7,"") -> 0.79617302 | G11: =IFERROR(G10/G7,"") -> 0.69087185 | H11: =IFERROR(H10/H7,"") -> 0.98823514 | I11: =IFERROR(I10/I7,"") -> 1.4297854 | ... BF11: =IFERROR(BF10/BF7,"") -> 0.43361255
A12: Dunya %of Express | B12: =IFERROR(B10/B9,"") -> 2.3555346 | C12: =IFERROR(C10/C9,"") -> 2.1220792 | D12: =IFERROR(D10/D9,"") -> 1.625 | E12: =IFERROR(E10/E9,"") -> 1.2 | F12: =IFERROR(F10/F9,"") -> 3.1052971 | G12: =IFERROR(G10/G9,"") -> 1.3557273 | H12: =IFERROR(H10/H9,"") -> 7.141773 | I12: =IFERROR(I10/I9,"") -> 2.8996006 | ... BE12: =IFERROR(BE10/BE9,"") -> 1.2174591 | BF12: =IFERROR(BF9/BF10,"") -> 0.75003965
A13: % Market share | B13: =IFERROR(B10/(SUM(B7:B10)),"") -> 0.40732301 | C13: =IFERROR(C10/(SUM(C7:C10)),"") -> 0.3194831 | D13: =IFERROR(D10/(SUM(D7:D10)),"") -> 0.30952381 | E13: =IFERROR(E10/(SUM(E7:E10)),"") -> 0.32142857 | F13: =IFERROR(F10/(SUM(F7:F10)),"") -> 0.33917591 | G13: =IFERROR(G10/(SUM(G7:G10)),"") -> 0.27956013 | H13: =IFERROR(H10/(SUM(H7:H10)),"") -> 0.41023754 | I13: =IFERROR(I10/(SUM(I7:I10)),"") -> 0.43145643 | ... BF13: =IFERROR(BF10/(SUM(BF7:BF10)),"") -> 0.22142801
A16: ENGLISH DAILIES
A17: Dawn | B17: 2.951402 | C17: 1.951152 | D17: 3.5 | E17: 1.7 | F17: 4.758676 | G17: 3.709633 | H17: 2.788187 | I17: 3.753219 | J17: 3.518381 | K17: 3.499557 | L17: 3.651924 | M17: 5.162276 | N17: 4.223199 | O17: 4.933044 | P17: 6.432406 | Q17: 2.240695 | R17: 8.221945 | S17: 5.363271 | T17: 3.948154 | U17: 4.945091 | V17: 3.81963 | W17: 5.441662 | X17: 8.065563 | Y17: 6.08723 | Z17: 5.007257 | AA17: 3.2725 | AB17: 3.658168 | AC17: 3.475425 | AD17: 6.10341 | AE17: 6.804263 | AF17: 2.294651 | AG17: 5.503244 | AH17: 2.72 | AI17: 5.170824 | AJ17: 5.427591 | AK17: 7.922926 | AL17: 4.613798 | AM17: 5.311131 | AN17: 8.58 | AO17: 5.42348 | AP17: 6.632195 | AQ17: 6.57 | AR17: 5.065865 | AS17: 6.694883 | AT17: 6.019576 | AU17: 2.65 | AV17: 0.281214 | AW17: 0.083396 | AX17: 0.037153 | AY17: 0.033075 | AZ17: 0.576944 | BA17: 0.48 | BB17: 1.4 | BC17: 0.95 | BD17: 0.93 | BE17: 0.133773 | BF17: =SUM(OFFSET(BF17,0,-1,):OFFSET(BF17,0,-8)) -> 4.540945
A18: The News | B18: 0.378083 | C18: 0.339292 | D18: 0.7 | E18: 0.5 | F18: 1.247253 | G18: 1.371172 | H18: 1.225572 | I18: 0.767275 | J18: 1.069058 | K18: 1.510103 | L18: 1.246025 | M18: 1.865626 | N18: 1.934144 | O18: 1.274461 | P18: 0.286771 | Q18: 0.349383 | R18: 2.105488 | S18: 1.76663 | T18: 2.289104 | U18: 1.012408 | V18: 1.908278 | W18: 2.761346 | X18: 3.179387 | Y18: 2.461293 | Z18: 2.088815 | AA18: 1.468698 | AB18: 1.90153 | AC18: 2.101074 | AD18: 3.078425 | AE18: 2.345292 | AF18: 3.947631 | AG18: 3.070229 | AH18: 3.48 | AI18: 1.482551 | AJ18: 0.950218 | AK18: 1.766551 | AL18: 1.403786 | AM18: 1.33732 | AN18: 1.62 | AO18: 1.396415 | AP18: 3.905142 | AQ18: 4.01 | AR18: 3.591508 | AS18: 4.19272 | AT18: 3.785916 | AU18: 3.21 | AV18: 7.923234 | AW18: 5.854433 | AX18: 4.447672 | AY18: 4.308925 | AZ18: 6.714905 | BA18: 3.81 | BB18: 5.44 | BC18: 5.46 | BD18: 6.59 | BE18: 1.114005 | BF18: =SUM(OFFSET(BF18,0,-1,):OFFSET(BF18,0,-8)) -> 37.885507
A19: The Nation | B19: 1.131262 | C19: 0.371413 | D19: 1.5 | E19: 0.9 | F19: 0.415161 | G19: 0.686373 | H19: 0.304166 | I19: 0.569461 | J19: 0.420458 | K19: 0.373287 | L19: 0.353614 | M19: 0.604065 | N19: 0.530314 | O19: 0.234016 | P19: 0.304439 | Q19: 0.290944 | R19: 0.362507 | S19: 0.254527 | T19: 0.25512 | U19: 0.276931 | V19: 0.39071 | W19: 1.05493 | X19: 0.789246 | Y19: 0.921719 | Z19: 0.56413 | AA19: 0.653518 | AB19: 0.536506 | AC19: 0.353835 | AD19: 0.658058 | AE19: 0.43673 | AF19: 0.649395 | AG19: 0.501743 | AH19: 0.77 | AI19: 0.652696 | AJ19: 0.451407 | AK19: 0.701912 | AL19: 0.549074 | AM19: 0.354365 | AN19: 1.4 | AO19: 0.499979 | AP19: 0.617208 | AQ19: 0.96 | AR19: 0.715545 | AS19: 0.688358 | AT19: 0.689764 | AU19: 0.56 | AV19: 1.489264 | AW19: 1.880253 | AX19: 1.030437 | AY19: 1.1306 | AZ19: 1.548962 | BA19: 0.99 | BB19: 1.03 | BC19: 1 | BD19: 0.45 | BE19: 0.14518 | BF19: =SUM(OFFSET(BF19,0,-1,):OFFSET(BF19,0,-8)) -> 7.325179
A20: Express Tribune | B20: 1.495873 | C20: 0.620766 | D20: 1.7 | E20: 1 | F20: 1.009196 | G20: 1.439434 | H20: 0.675031 | I20: 1.971488 | J20: 2.839953 | K20: 2.256225 | L20: 1.237137 | M20: 1.471249 | N20: 1.596752 | O20: 1.200208 | P20: 2.283781 | Q20: 1.298374 | R20: 1.239839 | S20: 0.9905 | T20: 0.883215 | U20: 2.068274 | V20: 1.363858 | W20: 1.884199 | X20: 1.972792 | Y20: 1.618042 | Z20: 1.485076 | AA20: 1.136699 | AB20: 1.080215 | AC20: 1.257793 | AD20: 1.308056 | AE20: 1.472912 | AF20: 2.691965 | AG20: 2.894302 | AH20: 1.44 | AI20: 1.341708 | AJ20: 2.055301 | AK20: 2.403456 | AL20: 0.930755 | AM20: 1.485433 | AN20: 1.74 | AO20: 1.777371 | AP20: 2.506459 | AQ20: 3.49 | AR20: 3.262595 | AS20: 3.057198 | AT20: 2.922903 | AU20: 2.23 | AV20: 7.939713 | AW20: 5.73411 | AX20: 3.911537 | AY20: 4.079137 | AZ20: 7.596285 | BA20: 4.73 | BB20: 5.52 | BC20: 5.93 | BD20: 7.13 | BE20: 1.798276 | BF20: =SUM(OFFSET(BF20,0,-1,):OFFSET(BF20,0,-8)) -> 40.695235
A21: % of Dawn | B21: =IFERROR(B20/B17,"") -> 0.50683472 | C21: =IFERROR(C20/C17,"") -> 0.31815358 | D21: =IFERROR(D20/D17,"") -> 0.48571429 | E21: =IFERROR(E20/E17,"") -> 0.58823529 | F21: =IFERROR(F20/F17,"") -> 0.21207496 | G21: =IFERROR(G20/G17,"") -> 0.38802599 | H21: =IFERROR(H20/H17,"") -> 0.24210392 | I21: =IFERROR(I20/I17,"") -> 0.52527923 | ... BE21: =IFERROR(BE20/BE17,"") -> 13.442743 | BF21: =IFERROR(BF19/BF17,"") -> 1.6131398
A22: % of News | B22: =IFERROR(B20/B18,"") -> 3.9564672 | C22: =IFERROR(C20/C18,"") -> 1.8295922 | D22: =IFERROR(D20/D18,"") -> 2.4285714 | E22: =IFERROR(E20/E18,"") -> 2 | F22: =IFERROR(F20/F18,"") -> 0.80913495 | G22: =IFERROR(G20/G18,"") -> 1.0497837 | H22: =IFERROR(H20/H18,"") -> 0.55078853 | I22: =IFERROR(I20/I18,"") -> 2.5694673 | ... BF22: =IFERROR(BF20/BF18,"") -> 1.0741637
A23: % Market share | B23: =IFERROR(B20/(SUM(B17:B20)),"") -> 0.25112782 | C23: =IFERROR(C20/(SUM(C17:C20)),"") -> 0.1891067 | D23: =IFERROR(D20/(SUM(D17:D20)),"") -> 0.22972973 | E23: =IFERROR(E20/(SUM(E17:E20)),"") -> 0.24390244 | F23: =IFERROR(F20/(SUM(F17:F20)),"") -> 0.13582196 | G23: =IFERROR(G20/(SUM(G17:G20)),"") -> 0.19973796 | H23: =IFERROR(H20/(SUM(H17:H20)),"") -> 0.13519667 | I23: =IFERROR(I20/(SUM(I17:I20)),"") -> 0.27919053 | ... BF23: =IFERROR(BF20/(SUM(BF17:BF20)),"") -> 0.44993527
A26: SINDHI DAILIES
A27: Kawish | B27: 0.568458 | C27: 0.131592 | D27: 0.32 | E27: 0.21 | F27: 0.360929 | G27: 0.566037 | H27: 0.149187 | I27: 0.066164 | J27: 0.242892 | K27: 0.177932 | L27: 0.147283 | M27: 0.500965 | N27: 0.22605 | O27: 0.191929 | P27: 0.131772 | Q27: 0.204213 | R27: 0.220997 | S27: 0.543918 | T27: 0.501934 | U27: 0.405713 | V27: 0.430936 | W27: 0.22022 | X27: 0.452329 | Y27: 0.972511 | Z27: 0.294863 | AA27: 0.364751 | AB27: 0.128358 | AC27: 0.105244 | AD27: 0.061173 | AE27: 0.366571 | AF27: 0.750142 | AG27: 0.644441 | AH27: 0.39 | AI27: 0.501509 | AJ27: 0.522569 | AK27: 2.003413 | AL27: 0.955909 | AM27: 0.171358 | AN27: 0.52 | AO27: 0.492872 | AP27: 0.710123 | AQ27: 0.98 | AR27: 0.094373 | AS27: 0.689366 | AT27: 0.578189 | AU27: 0.920981 | AV27: 0.597057 | AW27: 0.50445 | AX27: 0.090118 | AY27: 0.656397 | AZ27: 0.32397 | BA27: 0.207942 | BB27: 0.21 | BC27: 0.79 | BD27: 0.477039 | BE27: 0.024394 | BF27: =SUM(OFFSET(BF27,0,-1,):OFFSET(BF27,0,-8)) -> 2.77986
A28: Ibrat | B28: 0.119025 | C28: 0.082362 | D28: 0.1 | E28: 0.06 | F28: 0.015 | G28: 0.163628 | H28: 0.026332 | I28: 0.172764 | J28: 0.211 | K28: 0.030904 | L28: 0.171682 | M28: 0.213522 | N28: 0.277668 | O28: 0.093452 | P28: 0.256038 | Q28: 0.231577 | R28: 0.818947 | S28: 0.572997 | T28: 0.378809 | U28: 0.330581 | V28: 0.499636 | W28: 0.334334 | X28: 0.184537 | Y28: 0.371951 | Z28: 0.151406 | AA28: 0.290994 | AB28: 0.215576 | AC28: 0.19907 | AD28: 0.173593 | AE28: 0.352064 | AF28: 0.277132 | AG28: 0.273919 | AH28: 0.26 | AI28: 0.224841 | AJ28: 0.155372 | AK28: 0.254527 | AL28: 0.130441 | AM28: 0.104538 | AN28: 0.37 | AO28: 0.193015 | AP28: 0.240804 | AQ28: 0.163027 | AR28: 0.245427 | AS28: 0.34016 | AT28: 0.360456 | AU28: 0.26134 | AV28: 0.323518 | AW28: 0.106899 | AX28: 0.042904 | AY28: 0.22999 | AZ28: 0.183365 | BA28: 0.18 | BB28: 0.35 | BC28: 0.173008 | BD28: 0.098893 | BE28: 0.045841 | BF28: =SUM(OFFSET(BF28,0,-1,):OFFSET(BF28,0,-8)) -> 1.304001
A29: Awami Awaz | B29: 0.206626 | C29: 0.190701 | D29: 0.44 | E29: 0.22 | F29: 0.55539 | G29: 0.17834 | H29: 0.181239 | I29: 0.621684 | J29: 0.248061 | K29: 0.32728 | L29: 0.316563 | M29: 0.555493 | N29: 0.865953 | O29: 0.401424 | P29: 0.4259 | Q29: 0.458726 | R29: 0.714839 | S29: 0.543918 | T29: 0.228794 | U29: 0.405967 | V29: 0.458566 | W29: 0.543927 | X29: 0.581093 | Y29: 0.65522 | Z29: 0.29148 | AA29: 0.19998 | AB29: 0.347707 | AC29: 0.458333 | AD29: 0.20288 | AE29: 0.448346 | AF29: 0.627533 | AG29: 0.503226 | AH29: 0.431953 | AI29: 0.375763 | AJ29: 0.54118 | AK29: 0.62488 | AL29: 0.25591 | AM29: 0.364249 | AN29: 0.44 | AO29: 0.15536 | AP29: 0.257733 | AQ29: 0.2 | AR29: 0.43291 | AS29: 0.974899 | AT29: 0.267747 | AU29: 0.37 | AV29: 0.885126 | AW29: 0.704883 | AX29: 0.583003 | AY29: 0.354146 | AZ29: 0.465447 | BA29: 0.20628 | BB29: 0.57 | BC29: 0.76 | BD29: 0.402375 | BE29: 0 | BF29: =SUM(OFFSET(BF29,0,-1,):OFFSET(BF29,0,-8)) -> 3.341251
A30: Sobh | AE30: 0 | AR30: 0 | BF30: =SUM(OFFSET(BF30,0,-1,):OFFSET(BF30,0,-8)) -> 0
A31: Sindh Express | B31: 0.01 | C31: 0 | D31: 0.05 | E31: 0 | F31: 0.02 | G31: 0.042606 | H31: 0.091 | I31: 0.263634 | K31: 0.087747 | L31: 0.05 | M31: 0.054 | N31: 0.054 | O31: 0.06 | P31: 0 | Q31: 0.051227 | R31: 0.054 | S31: 0 | T31: 0 | U31: 0 | V31: 0.126802 | W31: 0.008115 | X31: 0.06 | Y31: 0 | Z31: 0 | AA31: 0 | AB31: 0 | AC31: 0.01 | AD31: 0 | AE31: 0.015216 | AF31: 0.128 | AG31: 0.028 | AH31: 0.05 | AI31: 0 | AJ31: 0 | AK31: 0.109606 | AL31: 0 | AM31: 0.013 | AN31: 0.02 | AO31: 0.086 | AP31: 0.016 | AQ31: 0 | AR31: 0 | AS31: 0.13 | AT31: 0 | AU31: 0 | AV31: 0.028404 | AW31: 0 | AX31: 0 | AY31: 0 | AZ31: 0.01826 | BA31: 0.020288 | BB31: 0 | BC31: 0.07 | BD31: 0.029925 | BE31: 0 | BF31: =SUM(OFFSET(BF31,0,-1,):OFFSET(BF31,0,-8)) -> 0.138473
A32: % of Kawish | B32: =IFERROR(B31/B27,"") -> 0.017591449 | C32: =IFERROR(C31/C27,"") -> 0 | D32: =IFERROR(D31/D27,"") -> 0.15625 | E32: =IFERROR(E31/E27,"") -> 0 | F32: =IFERROR(F31/F27,"") -> 0.05541256 | G32: =IFERROR(G31/G27,"") -> 0.075270698 | H32: =IFERROR(H31/H27,"") -> 0.60997272 | I32: =IFERROR(I31/I27,"") -> 3.9845535 | ... BF32: =IFERROR(BF31/BF27,"") -> 0.04981294
A33: % Market share | B33: =IFERROR(B31/(SUM(B27:B31)),"") -> 0.011060613 | C33: =IFERROR(C31/(SUM(C27:C31)),"") -> 0 | D33: =IFERROR(D31/(SUM(D27:D31)),"") -> 0.054945055 | E33: =IFERROR(E31/(SUM(E27:E31)),"") -> 0 | F33: =IFERROR(F31/(SUM(F27:F31)),"") -> 0.021023442 | G33: =IFERROR(G31/(SUM(G27:G31)),"") -> 0.044819595 | H33: =IFERROR(H31/(SUM(H27:H31)),"") -> 0.20323478 | I33: =IFERROR(I31/(SUM(I27:I31)),"") -> 0.2344985 | ... BF33: =IFERROR(BF31/(SUM(BF27:BF31)),"") -> 0.018307853
A36: Grading
A37: Total /Highest
A38: Medium (50% of Total)
A39: Lowest

Sheet FED-PID(L)
A1: Lahore PIDs Revenues (Federal Government)
A2: From 01/01/2021 To 05/8/2025
A4: Rs in million
B5: Jan'21 | C5: Feb'21 | D5: Mar'21 | E5: Apr'21 | F5: May'21 | G5: Jun'21 | H5: Jul'21 | I5: Aug'21 | J5: Sep'21 | K5: Oct'21 | L5: Nov'21 | M5: Dec'21 | N5: Jan'22 | O5: Feb'22 | P5: Mar'22 | Q5: Apr'22 | R5: May'22 | S5: Jun'22 | T5: Jul'22 | U5: Aug'22 | V5: Sep'22 | W5: Oct'22 | X5: Nov'22 | Y5: Dec'22 | Z5: Jan'23 | AA5: Feb'23 | AB5: Mar'23 | AC5: Apr'23 | AD5: May'23 | AE5: Jun'23 | AF5: Jul'23 | AG5: Aug'23 | AH5: Sep'23 | AI5: Oct'23 | AJ5: Nov'23 | AK5: Dec'23 | AL5: Jan'24 | AM5: Feb'24 | AN5: Mar'24 | AO5: Apr'24 | AP5: May'24 | AQ5: Jun'24 | AR5: ='FED-PID(ALL)'!AR5 -> Jul'24 | AS5: ='FED-PID(ALL)'!AS5 -> Aug'24 | AT5: ='FED-PID(ALL)'!AT5 -> Sep'24 | AU5: ='FED-PID(ALL)'!AU5 -> Oct'24 | AV5: ='FED-PID(ALL)'!AV5 -> Nov'24 | AW5: ='FED-PID(ALL)'!AW5 -> Dec'24 | AX5: ='FED-PID(ALL)'!AX5 -> Jan'25 | AY5: ='FED-PID(ALL)'!AY5 -> Feb'25 | ... BD5: ='FED-PID(ALL)'!BD5 -> Jul'25 | BE5: 1-5-Aug'25 | BF5: TOTAL
A6: URDU DAILIES
A7: Jang | B7: 1.674644 | C7: 1.134093 | D7: 1.2 | E7: 0.4 | F7: 0.829423 | G7: 0.69518 | H7: 0.818567 | I7: 0.700689 | J7: 1.838118 | K7: 1.726094 | L7: 2.430416 | M7: 7.451894 | N7: 4.676241 | O7: 1.958768 | P7: 0.474071 | Q7: 1.621023 | R7: 2.979085 | S7: 2.695308 | T7: 2.230444 | U7: 2.215453 | V7: 4.223681 | W7: 3.38231 | X7: 2.969672 | Y7: 4.52988 | Z7: 3.435362 | AA7: 3.528001 | AB7: 2.564322 | AC7: 3.329073 | AD7: 2.306122 | AE7: 4.299891 | AF7: 5.081638 | AG7: 4.255771 | AH7: 5.47 | AI7: 2.333933 | AJ7: 1.353246 | AK7: 3.48236 | AL7: 3.343499 | AM7: 1.385956 | AN7: 4.47 | AO7: 3.878412 | AP7: 6.168919 | AQ7: 6.52 | AR7: 5.678438 | AS7: 6.720592 | AT7: 4.233543 | AU7: 4.39 | AV7: 4.774066 | AW7: 8.916891 | AX7: 7.532859 | AY7: 5.437969 | AZ7: 4.437766 | BA7: 3.67 | BB7: 6.06 | BC7: 4 | BD7: 4.2 | BE7: 0.757306 | BF7: =SUM(OFFSET(BF7,0,-1,):OFFSET(BF7,0,-8)) -> 36.0959
A8: Nawa-e-Waqt | B8: 1.708733 | C8: 1.548272 | D8: 1.6 | E8: 1.2 | F8: 1.363317 | G8: 2.265465 | H8: 1.686868 | I8: 2.548981 | J8: 2.403331 | K8: 2.717983 | L8: 3.354585 | M8: 3.880864 | N8: 2.050744 | O8: 1.499841 | P8: 4.582111 | Q8: 1.844508 | R8: 1.227479 | S8: 1.788467 | T8: 1.598613 | U8: 0.86029 | V8: 1.29939 | W8: 1.765011 | X8: 2.312933 | Y8: 2.157249 | Z8: 1.346448 | AA8: 1.17567 | AB8: 1.528008 | AC8: 1.547123 | AD8: 0.995743 | AE8: 1.193124 | AF8: 1.534012 | AG8: 1.934749 | AH8: 1.66 | AI8: 1.608455 | AJ8: 1.224948 | AK8: 1.214237 | AL8: 0.879106 | AM8: 0.743141 | AN8: 1.31 | AO8: 2.567525 | AP8: 2.443531 | AQ8: 1.5 | AR8: 1.694068 | AS8: 2.589105 | AT8: 1.429327 | AU8: 1.68 | AV8: 1.217235 | AW8: 2.247178 | AX8: 1.457645 | AY8: 0.993855 | AZ8: 1.314653 | BA8: 2.01 | BB8: 1.43 | BC8: 1.54 | BD8: 1.28 | BE8: 0.210257 | BF8: =SUM(OFFSET(BF8,0,-1,):OFFSET(BF8,0,-8)) -> 10.23641
